Workbook

Sheet Venta
Z1: Planta | AA1: (Todas) | AD1: Planta | AE1: ENAMI | AK1: Planta | AL1: (Todas)
B2: Venta Minerales 2026 | Q2: Fecha | R2: (Varios elementos) | V2: Fecha | W2: (Varios elementos) | Z2: Fecha | AA2: (Varios elementos) | AD2: Fecha | AE2: (Todas) | AK2: Fecha | AL2: (Todas)
B4: N° Lote | C4: Recargo | D4: Patente | E4: Fecha | F4: Ton | G4: Padron | H4: Planta | I4: Mineral | J4: 9 | L4: Fecha | M4: N° Viajes | N4: Ton. | Q4: Planta | R4: Padron | S4: N° Viajes | T4: Ton. | V4: Fecha | W4: N° Viajes | X4: Ton. | Z4: Fecha | AA4: N° Viajes | AB4: Ton. | AD4: Cuenta de Recargo | AG4: Etiquetas de fila | AH4: Cuenta de Recargo | AI4: Promedio de Ton | AK4: Suma de Ton | AN4: Planta | AO4: (Todas)
B5: CN001 | C5: 1 | D5: PYCH-48 | E5: 46035 | F5: 27.35 | G5: {=IF( Venta4[[#This Row],[N° Lote]]="", "", IFERROR( INDEX( Mezcla!R:R, _xlfn.XLOOKUP(Venta4[[#This Row],[N° Lote]],Mezcla!R:R,ROW(Mezcla!R:R))+1 ), "" ) )} -> 3H COPPER EL SAUCE 1 AL 5 | H5: =IF( Venta4[[#This Row],[N° Lote]]="", "", IF( LEFT(Venta4[[#This Row],[N° Lote]],2)="CN", "CERRO NEGRO", IF( AND( ISNUMBER(VALUE(Venta4[[#This Row],[N° Lote]])), LEN(Venta4[[#This Row],[N° Lote]])=4 ), "CEMIN", IF( AND( ISNUMBER(VALUE(Venta4[[#This Row],[N° Lote]])), LEN(Venta4[[#This Row],[N° Lote]])>4 ), "ENAMI", "ORIGEN NO DEFINIDO" ) ) ) ) -> CERRO NEGRO | I5: =IF( Venta4[[#This Row],[N° Lote]]="", "", IF( LEFT(Venta4[[#This Row],[N° Lote]],2)="CN", "Óxido", IF( AND( ISNUMBER(VALUE(Venta4[[#This Row],[N° Lote]])), LEN(Venta4[[#This Row],[N° Lote]])=4 ), "Óxido", IF( AND( ISNUMBER(VALUE(Venta4[[#This Row],[N° Lote]])), LEN(Venta4[[#This Row],[N° Lote]])>4 ), "Sulfuro", "" ) ) ) ) -> Óxido | L5: jul | M5: 16 | N5: 500.99 | Q5: ENAMI | V5: ENAMI | W5: 9 | X5: 279.7 | Z5: 60001 | AA5: 4 | AB5: 122.52 | AD5: 196 | AG5: CERRO NEGRO | AH5: 65 | AI5: 32.272308 | AK5: 8350.47
B6: CN001 | C6: 2 | D6: JKDK-25 | E6: 46035 | F6: 30.41 | G6: {=IF( Venta4[[#This Row],[N° Lote]]="", "", IFERROR( INDEX( Mezcla!R:R, _xlfn.XLOOKUP(Venta4[[#This Row],[N° Lote]],Mezcla!R:R,ROW(Mezcla!R:R))+1 ), "" ) )} -> 3H COPPER EL SAUCE 1 AL 5 | H6: =IF( Venta4[[#This Row],[N° Lote]]="", "", IF( LEFT(Venta4[[#This Row],[N° Lote]],2)="CN", "CERRO NEGRO", IF( AND( ISNUMBER(VALUE(Venta4[[#This Row],[N° Lote]])), LEN(Venta4[[#This Row],[N° Lote]])=4 ), "CEMIN", IF( AND( ISNUMBER(VALUE(Venta4[[#This Row],[N° Lote]])), LEN(Venta4[[#This Row],[N° Lote]])>4 ), "ENAMI", "ORIGEN NO DEFINIDO" ) ) ) ) -> CERRO NEGRO | I6: =IF( Venta4[[#This Row],[N° Lote]]="", "", IF( LEFT(Venta4[[#This Row],[N° Lote]],2)="CN", "Óxido", IF( AND( ISNUMBER(VALUE(Venta4[[#This Row],[N° Lote]])), LEN(Venta4[[#This Row],[N° Lote]])=4 ), "Óxido", IF( AND( ISNUMBER(VALUE(Venta4[[#This Row],[N° Lote]])), LEN(Venta4[[#This Row],[N° Lote]])>4 ), "Sulfuro", "" ) ) ) ) -> Óxido | L6: 01-jul | M6: 7 | N6: 221.21 | R6: Minera la Cruz | S6: 4 | T6: 123.52 | V6: RBWX-10 | W6: 1 | X6: 32.45 | Z6: 60002 | AA6: 4 | AB6: 120.21 | AG6: ENAMI | AH6: 196 | AI6: 30.783827 | AN6: Fecha | AO6: N° Viajes | AP6: Ton.
B7: CN001 | C7: 3 | D7: LCGZ-26 | E7: 46035 | F7: 27.69 | G7: {=IF( Venta4[[#This Row],[N° Lote]]="", "", IFERROR( INDEX( Mezcla!R:R, _xlfn.XLOOKUP(Venta4[[#This Row],[N° Lote]],Mezcla!R:R,ROW(Mezcla!R:R))+1 ), "" ) )} -> 3H COPPER EL SAUCE 1 AL 5 | H7: =IF( Venta4[[#This Row],[N° Lote]]="", "", IF( LEFT(Venta4[[#This Row],[N° Lote]],2)="CN", "CERRO NEGRO", IF( AND( ISNUMBER(VALUE(Venta4[[#This Row],[N° Lote]])), LEN(Venta4[[#This Row],[N° Lote]])=4 ), "CEMIN", IF( AND( ISNUMBER(VALUE(Venta4[[#This Row],[N° Lote]])), LEN(Venta4[[#This Row],[N° Lote]])>4 ), "ENAMI", "ORIGEN NO DEFINIDO" ) ) ) ) -> CERRO NEGRO | I7: =IF( Venta4[[#This Row],[N° Lote]]="", "", IF( LEFT(Venta4[[#This Row],[N° Lote]],2)="CN", "Óxido", IF( AND( ISNUMBER(VALUE(Venta4[[#This Row],[N° Lote]])), LEN(Venta4[[#This Row],[N° Lote]])=4 ), "Óxido", IF( AND( ISNUMBER(VALUE(Venta4[[#This Row],[N° Lote]])), LEN(Venta4[[#This Row],[N° Lote]])>4 ), "Sulfuro", "" ) ) ) ) -> Óxido | L7: 03-jul | M7: 5 | N7: 157.46 | R7: 3H COPPER El SAUCE | S7: 7 | T7: 221.21 | V7: PYCH-48 | W7: 3 | X7: 92.99 | Z7: 60011 | AA7: 5 | AB7: 149.76 | AN7: <13-01-2026
B8: CN001 | C8: 4 | D8: PYCH-48 | E8: 46036 | F8: 29.16 | G8: {=IF( Venta4[[#This Row],[N° Lote]]="", "", IFERROR( INDEX( Mezcla!R:R, _xlfn.XLOOKUP(Venta4[[#This Row],[N° Lote]],Mezcla!R:R,ROW(Mezcla!R:R))+1 ), "" ) )} -> 3H COPPER EL SAUCE 1 AL 5 | H8: =IF( Venta4[[#This Row],[N° Lote]]="", "", IF( LEFT(Venta4[[#This Row],[N° Lote]],2)="CN", "CERRO NEGRO", IF( AND( ISNUMBER(VALUE(Venta4[[#This Row],[N° Lote]])), LEN(Venta4[[#This Row],[N° Lote]])=4 ), "CEMIN", IF( AND( ISNUMBER(VALUE(Venta4[[#This Row],[N° Lote]])), LEN(Venta4[[#This Row],[N° Lote]])>4 ), "ENAMI", "ORIGEN NO DEFINIDO" ) ) ) ) -> CERRO NEGRO | I8: =IF( Venta4[[#This Row],[N° Lote]]="", "", IF( LEFT(Venta4[[#This Row],[N° Lote]],2)="CN", "Óxido", IF( AND( ISNUMBER(VALUE(Venta4[[#This Row],[N° Lote]])), LEN(Venta4[[#This Row],[N° Lote]])=4 ), "Óxido", IF( AND( ISNUMBER(VALUE(Venta4[[#This Row],[N° Lote]])), LEN(Venta4[[#This Row],[N° Lote]])>4 ), "Sulfuro", "" ) ) ) ) -> Óxido | L8: 06-jul | M8: 4 | N8: 122.32 | R8: Procesos Mineros | S8: 5 | T8: 156.26 | V8: LCGZ-26 | W8: 2 | X8: 62.48 | Z8: 60013 | AA8: 5 | AB8: 152.07 | AG8: CEMIN | AH8: 5 | AI8: 32.228 | AN8: (en blanco)
B9: CN001 | C9: 5 | D9: LCGZ-26 | E9: 46036 | F9: 29.22 | G9: {=IF( Venta4[[#This Row],[N° Lote]]="", "", IFERROR( INDEX( Mezcla!R:R, _xlfn.XLOOKUP(Venta4[[#This Row],[N° Lote]],Mezcla!R:R,ROW(Mezcla!R:R))+1 ), "" ) )} -> 3H COPPER EL SAUCE 1 AL 5 | H9: =IF( Venta4[[#This Row],[N° Lote]]="", "", IF( LEFT(Venta4[[#This Row],[N° Lote]],2)="CN", "CERRO NEGRO", IF( AND( ISNUMBER(VALUE(Venta4[[#This Row],[N° Lote]])), LEN(Venta4[[#This Row],[N° Lote]])=4 ), "CEMIN", IF( AND( ISNUMBER(VALUE(Venta4[[#This Row],[N° Lote]])), LEN(Venta4[[#This Row],[N° Lote]])>4 ), "ENAMI", "ORIGEN NO DEFINIDO" ) ) ) ) -> CERRO NEGRO | I9: =IF( Venta4[[#This Row],[N° Lote]]="", "", IF( LEFT(Venta4[[#This Row],[N° Lote]],2)="CN", "Óxido", IF( AND( ISNUMBER(VALUE(Venta4[[#This Row],[N° Lote]])), LEN(Venta4[[#This Row],[N° Lote]])=4 ), "Óxido", IF( AND( ISNUMBER(VALUE(Venta4[[#This Row],[N° Lote]])), LEN(Venta4[[#This Row],[N° Lote]])>4 ), "Sulfuro", "" ) ) ) ) -> Óxido | L9: Total general | M9: 16 | N9: 500.99 | Q9: Total ENAMI | S9: 16 | T9: 500.99 | V9: JKDK-25 | W9: 3 | X9: 91.78 | Z9: 60019 | AA9: 5 | AB9: 152.45 | AG9: ORIGEN NO DEFINIDO | AH9: 2 | AI9: 29 | AN9: ene | AO9: 29 | AP9: 860.49
B10: CN001 | C10: 6 | D10: RBWX-10 | E10: 46036 | F10: 28.87 | G10: {=IF( Venta4[[#This Row],[N° Lote]]="", "", IFERROR( INDEX( Mezcla!R:R, _xlfn.XLOOKUP(Venta4[[#This Row],[N° Lote]],Mezcla!R:R,ROW(Mezcla!R:R))+1 ), "" ) )} -> 3H COPPER EL SAUCE 1 AL 5 | H10: =IF( Venta4[[#This Row],[N° Lote]]="", "", IF( LEFT(Venta4[[#This Row],[N° Lote]],2)="CN", "CERRO NEGRO", IF( AND( ISNUMBER(VALUE(Venta4[[#This Row],[N° Lote]])), LEN(Venta4[[#This Row],[N° Lote]])=4 ), "CEMIN", IF( AND( ISNUMBER(VALUE(Venta4[[#This Row],[N° Lote]])), LEN(Venta4[[#This Row],[N° Lote]])>4 ), "ENAMI", "ORIGEN NO DEFINIDO" ) ) ) ) -> CERRO NEGRO | I10: =IF( Venta4[[#This Row],[N° Lote]]="", "", IF( LEFT(Venta4[[#This Row],[N° Lote]],2)="CN", "Óxido", IF( AND( ISNUMBER(VALUE(Venta4[[#This Row],[N° Lote]])), LEN(Venta4[[#This Row],[N° Lote]])=4 ), "Óxido", IF( AND( ISNUMBER(VALUE(Venta4[[#This Row],[N° Lote]])), LEN(Venta4[[#This Row],[N° Lote]])>4 ), "Sulfuro", "" ) ) ) ) -> Óxido | Q10: Total general | S10: 16 | T10: 500.99 | V10: Total general | W10: 9 | X10: 279.7 | Z10: 60022 | AA10: 5 | AB10: 157.43 | AG10: Total general | AH10: 268 | AI10: 31.15847 | AN10: 13-ene | AO10: 3 | AP10: 85.45
B11: CN002 | C11: 1 | D11: PYCH-48 | E11: 46036 | F11: 28.88 | G11: {=IF( Venta4[[#This Row],[N° Lote]]="", "", IFERROR( INDEX( Mezcla!R:R, _xlfn.XLOOKUP(Venta4[[#This Row],[N° Lote]],Mezcla!R:R,ROW(Mezcla!R:R))+1 ), "" ) )} -> 3H COPPER EL SAUCE 1 AL 5 | H11: =IF( Venta4[[#This Row],[N° Lote]]="", "", IF( LEFT(Venta4[[#This Row],[N° Lote]],2)="CN", "CERRO NEGRO", IF( AND( ISNUMBER(VALUE(Venta4[[#This Row],[N° Lote]])), LEN(Venta4[[#This Row],[N° Lote]])=4 ), "CEMIN", IF( AND( ISNUMBER(VALUE(Venta4[[#This Row],[N° Lote]])), LEN(Venta4[[#This Row],[N° Lote]])>4 ), "ENAMI", "ORIGEN NO DEFINIDO" ) ) ) ) -> CERRO NEGRO | I11: =IF( Venta4[[#This Row],[N° Lote]]="", "", IF( LEFT(Venta4[[#This Row],[N° Lote]],2)="CN", "Óxido", IF( AND( ISNUMBER(VALUE(Venta4[[#This Row],[N° Lote]])), LEN(Venta4[[#This Row],[N° Lote]])=4 ), "Óxido", IF( AND( ISNUMBER(VALUE(Venta4[[#This Row],[N° Lote]])), LEN(Venta4[[#This Row],[N° Lote]])>4 ), "Sulfuro", "" ) ) ) ) -> Óxido | O11: =+SUM(N6:N10) -> 1001.98 | Z11: 60029 | AA11: 5 | AB11: 152.03 | AN11: 14-ene | AO11: 5 | AP11: 145.84
B12: CN002 | C12: 2 | D12: LCGZ-26 | E12: 46036 | F12: 29.71 | G12: {=IF( Venta4[[#This Row],[N° Lote]]="", "", IFERROR( INDEX( Mezcla!R:R, _xlfn.XLOOKUP(Venta4[[#This Row],[N° Lote]],Mezcla!R:R,ROW(Mezcla!R:R))+1 ), "" ) )} -> 3H COPPER EL SAUCE 1 AL 5 | H12: =IF( Venta4[[#This Row],[N° Lote]]="", "", IF( LEFT(Venta4[[#This Row],[N° Lote]],2)="CN", "CERRO NEGRO", IF( AND( ISNUMBER(VALUE(Venta4[[#This Row],[N° Lote]])), LEN(Venta4[[#This Row],[N° Lote]])=4 ), "CEMIN", IF( AND( ISNUMBER(VALUE(Venta4[[#This Row],[N° Lote]])), LEN(Venta4[[#This Row],[N° Lote]])>4 ), "ENAMI", "ORIGEN NO DEFINIDO" ) ) ) ) -> CERRO NEGRO | I12: =IF( Venta4[[#This Row],[N° Lote]]="", "", IF( LEFT(Venta4[[#This Row],[N° Lote]],2)="CN", "Óxido", IF( AND( ISNUMBER(VALUE(Venta4[[#This Row],[N° Lote]])), LEN(Venta4[[#This Row],[N° Lote]])=4 ), "Óxido", IF( AND( ISNUMBER(VALUE(Venta4[[#This Row],[N° Lote]])), LEN(Venta4[[#This Row],[N° Lote]])>4 ), "Sulfuro", "" ) ) ) ) -> Óxido | Z12: 60034 | AA12: 6 | AB12: 186.23 | AN12: 15-ene | AO12: 2 | AP12: 59.62
B13: CN002 | C13: 3 | D13: PYCH-48 | E13: 46037 | F13: 29.52 | G13: {=IF( Venta4[[#This Row],[N° Lote]]="", "", IFERROR( INDEX( Mezcla!R:R, _xlfn.XLOOKUP(Venta4[[#This Row],[N° Lote]],Mezcla!R:R,ROW(Mezcla!R:R))+1 ), "" ) )} -> 3H COPPER EL SAUCE 1 AL 5 | H13: =IF( Venta4[[#This Row],[N° Lote]]="", "", IF( LEFT(Venta4[[#This Row],[N° Lote]],2)="CN", "CERRO NEGRO", IF( AND( ISNUMBER(VALUE(Venta4[[#This Row],[N° Lote]])), LEN(Venta4[[#This Row],[N° Lote]])=4 ), "CEMIN", IF( AND( ISNUMBER(VALUE(Venta4[[#This Row],[N° Lote]])), LEN(Venta4[[#This Row],[N° Lote]])>4 ), "ENAMI", "ORIGEN NO DEFINIDO" ) ) ) ) -> CERRO NEGRO | I13: =IF( Venta4[[#This Row],[N° Lote]]="", "", IF( LEFT(Venta4[[#This Row],[N° Lote]],2)="CN", "Óxido", IF( AND( ISNUMBER(VALUE(Venta4[[#This Row],[N° Lote]])), LEN(Venta4[[#This Row],[N° Lote]])=4 ), "Óxido", IF( AND( ISNUMBER(VALUE(Venta4[[#This Row],[N° Lote]])), LEN(Venta4[[#This Row],[N° Lote]])>4 ), "Sulfuro", "" ) ) ) ) -> Óxido | Z13: 60040 | AA13: 6 | AB13: 184.64 | AN13: 16-ene | AO13: 2 | AP13: 61.8
B14: CN002 | C14: 4 | D14: PYCH-48 | E14: 46037 | F14: 30.1 | G14: {=IF( Venta4[[#This Row],[N° Lote]]="", "", IFERROR( INDEX( Mezcla!R:R, _xlfn.XLOOKUP(Venta4[[#This Row],[N° Lote]],Mezcla!R:R,ROW(Mezcla!R:R))+1 ), "" ) )} -> 3H COPPER EL SAUCE 1 AL 5 | H14: =IF( Venta4[[#This Row],[N° Lote]]="", "", IF( LEFT(Venta4[[#This Row],[N° Lote]],2)="CN", "CERRO NEGRO", IF( AND( ISNUMBER(VALUE(Venta4[[#This Row],[N° Lote]])), LEN(Venta4[[#This Row],[N° Lote]])=4 ), "CEMIN", IF( AND( ISNUMBER(VALUE(Venta4[[#This Row],[N° Lote]])), LEN(Venta4[[#This Row],[N° Lote]])>4 ), "ENAMI", "ORIGEN NO DEFINIDO" ) ) ) ) -> CERRO NEGRO | I14: =IF( Venta4[[#This Row],[N° Lote]]="", "", IF( LEFT(Venta4[[#This Row],[N° Lote]],2)="CN", "Óxido", IF( AND( ISNUMBER(VALUE(Venta4[[#This Row],[N° Lote]])), LEN(Venta4[[#This Row],[N° Lote]])=4 ), "Óxido", IF( AND( ISNUMBER(VALUE(Venta4[[#This Row],[N° Lote]])), LEN(Venta4[[#This Row],[N° Lote]])>4 ), "Sulfuro", "" ) ) ) ) -> Óxido | Z14: 60042 | AA14: 5 | AB14: 156.29 | AN14: 19-ene | AO14: 4 | AP14: 114.08
B15: CN002 | C15: 5 | D15: LCGZ-26 | E15: 46038 | F15: 31.8 | G15: {=IF( Venta4[[#This Row],[N° Lote]]="", "", IFERROR( INDEX( Mezcla!R:R, _xlfn.XLOOKUP(Venta4[[#This Row],[N° Lote]],Mezcla!R:R,ROW(Mezcla!R:R))+1 ), "" ) )} -> 3H COPPER EL SAUCE 1 AL 5 | H15: =IF( Venta4[[#This Row],[N° Lote]]="", "", IF( LEFT(Venta4[[#This Row],[N° Lote]],2)="CN", "CERRO NEGRO", IF( AND( ISNUMBER(VALUE(Venta4[[#This Row],[N° Lote]])), LEN(Venta4[[#This Row],[N° Lote]])=4 ), "CEMIN", IF( AND( ISNUMBER(VALUE(Venta4[[#This Row],[N° Lote]])), LEN(Venta4[[#This Row],[N° Lote]])>4 ), "ENAMI", "ORIGEN NO DEFINIDO" ) ) ) ) -> CERRO NEGRO | I15: =IF( Venta4[[#This Row],[N° Lote]]="", "", IF( LEFT(Venta4[[#This Row],[N° Lote]],2)="CN", "Óxido", IF( AND( ISNUMBER(VALUE(Venta4[[#This Row],[N° Lote]])), LEN(Venta4[[#This Row],[N° Lote]])=4 ), "Óxido", IF( AND( ISNUMBER(VALUE(Venta4[[#This Row],[N° Lote]])), LEN(Venta4[[#This Row],[N° Lote]])>4 ), "Sulfuro", "" ) ) ) ) -> Óxido | Z15: 60051 | AA15: 5 | AB15: 152.42 | AN15: 20-ene | AO15: 3 | AP15: 83.25
B16: CN002 | C16: 6 | D16: PYCH-48 | E16: 46038 | F16: 30 | G16: {=IF( Venta4[[#This Row],[N° Lote]]="", "", IFERROR( INDEX( Mezcla!R:R, _xlfn.XLOOKUP(Venta4[[#This Row],[N° Lote]],Mezcla!R:R,ROW(Mezcla!R:R))+1 ), "" ) )} -> 3H COPPER EL SAUCE 1 AL 5 | H16: =IF( Venta4[[#This Row],[N° Lote]]="", "", IF( LEFT(Venta4[[#This Row],[N° Lote]],2)="CN", "CERRO NEGRO", IF( AND( ISNUMBER(VALUE(Venta4[[#This Row],[N° Lote]])), LEN(Venta4[[#This Row],[N° Lote]])=4 ), "CEMIN", IF( AND( ISNUMBER(VALUE(Venta4[[#This Row],[N° Lote]])), LEN(Venta4[[#This Row],[N° Lote]])>4 ), "ENAMI", "ORIGEN NO DEFINIDO" ) ) ) ) -> CERRO NEGRO | I16: =IF( Venta4[[#This Row],[N° Lote]]="", "", IF( LEFT(Venta4[[#This Row],[N° Lote]],2)="CN", "Óxido", IF( AND( ISNUMBER(VALUE(Venta4[[#This Row],[N° Lote]])), LEN(Venta4[[#This Row],[N° Lote]])=4 ), "Óxido", IF( AND( ISNUMBER(VALUE(Venta4[[#This Row],[N° Lote]])), LEN(Venta4[[#This Row],[N° Lote]])>4 ), "Sulfuro", "" ) ) ) ) -> Óxido | Z16: 60056 | AA16: 5 | AB16: 152.07 | AN16: 21-ene | AO16: 3 | AP16: 96.51
B17: CN003 | C17: 1 | D17: PYCH-48 | E17: 46041 | F17: 30 | G17: {=IF( Venta4[[#This Row],[N° Lote]]="", "", IFERROR( INDEX( Mezcla!R:R, _xlfn.XLOOKUP(Venta4[[#This Row],[N° Lote]],Mezcla!R:R,ROW(Mezcla!R:R))+1 ), "" ) )} -> 3H COPPER EL SAUCE 1 AL 5 | H17: =IF( Venta4[[#This Row],[N° Lote]]="", "", IF( LEFT(Venta4[[#This Row],[N° Lote]],2)="CN", "CERRO NEGRO", IF( AND( ISNUMBER(VALUE(Venta4[[#This Row],[N° Lote]])), LEN(Venta4[[#This Row],[N° Lote]])=4 ), "CEMIN", IF( AND( ISNUMBER(VALUE(Venta4[[#This Row],[N° Lote]])), LEN(Venta4[[#This Row],[N° Lote]])>4 ), "ENAMI", "ORIGEN NO DEFINIDO" ) ) ) ) -> CERRO NEGRO | I17: =IF( Venta4[[#This Row],[N° Lote]]="", "", IF( LEFT(Venta4[[#This Row],[N° Lote]],2)="CN", "Óxido", IF( AND( ISNUMBER(VALUE(Venta4[[#This Row],[N° Lote]])), LEN(Venta4[[#This Row],[N° Lote]])=4 ), "Óxido", IF( AND( ISNUMBER(VALUE(Venta4[[#This Row],[N° Lote]])), LEN(Venta4[[#This Row],[N° Lote]])>4 ), "Sulfuro", "" ) ) ) ) -> Óxido | O17: =+SUM(N12:N17) -> 0 | Z17: 60057 | AA17: 5 | AB17: 152.54 | AN17: 22-ene | AO17: 2 | AP17: 59.43
B18: CN003 | C18: 2 | D18: RBWX-10 | E18: 46041 | F18: 25.1 | G18: {=IF( Venta4[[#This Row],[N° Lote]]="", "", IFERROR( INDEX( Mezcla!R:R, _xlfn.XLOOKUP(Venta4[[#This Row],[N° Lote]],Mezcla!R:R,ROW(Mezcla!R:R))+1 ), "" ) )} -> 3H COPPER EL SAUCE 1 AL 5 | H18: =IF( Venta4[[#This Row],[N° Lote]]="", "", IF( LEFT(Venta4[[#This Row],[N° Lote]],2)="CN", "CERRO NEGRO", IF( AND( ISNUMBER(VALUE(Venta4[[#This Row],[N° Lote]])), LEN(Venta4[[#This Row],[N° Lote]])=4 ), "CEMIN", IF( AND( ISNUMBER(VALUE(Venta4[[#This Row],[N° Lote]])), LEN(Venta4[[#This Row],[N° Lote]])>4 ), "ENAMI", "ORIGEN NO DEFINIDO" ) ) ) ) -> CERRO NEGRO | I18: =IF( Venta4[[#This Row],[N° Lote]]="", "", IF( LEFT(Venta4[[#This Row],[N° Lote]],2)="CN", "Óxido", IF( AND( ISNUMBER(VALUE(Venta4[[#This Row],[N° Lote]])), LEN(Venta4[[#This Row],[N° Lote]])=4 ), "Óxido", IF( AND( ISNUMBER(VALUE(Venta4[[#This Row],[N° Lote]])), LEN(Venta4[[#This Row],[N° Lote]])>4 ), "Sulfuro", "" ) ) ) ) -> Óxido | Z18: XX01 | AA18: 2 | AB18: 58 | AN18: 23-ene | AO18: 1 | AP18: 31.81
B19: CN003 | C19: 3 | D19: LCGZ-26 | E19: 46041 | F19: 28.98 | G19: {=IF( Venta4[[#This Row],[N° Lote]]="", "", IFERROR( INDEX( Mezcla!R:R, _xlfn.XLOOKUP(Venta4[[#This Row],[N° Lote]],Mezcla!R:R,ROW(Mezcla!R:R))+1 ), "" ) )} -> 3H COPPER EL SAUCE 1 AL 5 | H19: =IF( Venta4[[#This Row],[N° Lote]]="", "", IF( LEFT(Venta4[[#This Row],[N° Lote]],2)="CN", "CERRO NEGRO", IF( AND( ISNUMBER(VALUE(Venta4[[#This Row],[N° Lote]])), LEN(Venta4[[#This Row],[N° Lote]])=4 ), "CEMIN", IF( AND( ISNUMBER(VALUE(Venta4[[#This Row],[N° Lote]])), LEN(Venta4[[#This Row],[N° Lote]])>4 ), "ENAMI", "ORIGEN NO DEFINIDO" ) ) ) ) -> CERRO NEGRO | I19: =IF( Venta4[[#This Row],[N° Lote]]="", "", IF( LEFT(Venta4[[#This Row],[N° Lote]],2)="CN", "Óxido", IF( AND( ISNUMBER(VALUE(Venta4[[#This Row],[N° Lote]])), LEN(Venta4[[#This Row],[N° Lote]])=4 ), "Óxido", IF( AND( ISNUMBER(VALUE(Venta4[[#This Row],[N° Lote]])), LEN(Venta4[[#This Row],[N° Lote]])>4 ), "Sulfuro", "" ) ) ) ) -> Óxido | Z19: 60065 | AA19: 6 | AB19: 188.13 | AN19: 26-ene | AO19: 1 | AP19: 29.16
B20: CN003 | C20: 4 | D20: PYCH-48 | E20: 46041 | F20: 30 | G20: {=IF( Venta4[[#This Row],[N° Lote]]="", "", IFERROR( INDEX( Mezcla!R:R, _xlfn.XLOOKUP(Venta4[[#This Row],[N° Lote]],Mezcla!R:R,ROW(Mezcla!R:R))+1 ), "" ) )} -> 3H COPPER EL SAUCE 1 AL 5 | H20: =IF( Venta4[[#This Row],[N° Lote]]="", "", IF( LEFT(Venta4[[#This Row],[N° Lote]],2)="CN", "CERRO NEGRO", IF( AND( ISNUMBER(VALUE(Venta4[[#This Row],[N° Lote]])), LEN(Venta4[[#This Row],[N° Lote]])=4 ), "CEMIN", IF( AND( ISNUMBER(VALUE(Venta4[[#This Row],[N° Lote]])), LEN(Venta4[[#This Row],[N° Lote]])>4 ), "ENAMI", "ORIGEN NO DEFINIDO" ) ) ) ) -> CERRO NEGRO | I20: =IF( Venta4[[#This Row],[N° Lote]]="", "", IF( LEFT(Venta4[[#This Row],[N° Lote]],2)="CN", "Óxido", IF( AND( ISNUMBER(VALUE(Venta4[[#This Row],[N° Lote]])), LEN(Venta4[[#This Row],[N° Lote]])=4 ), "Óxido", IF( AND( ISNUMBER(VALUE(Venta4[[#This Row],[N° Lote]])), LEN(Venta4[[#This Row],[N° Lote]])>4 ), "Sulfuro", "" ) ) ) ) -> Óxido | Z20: 60067 | AA20: 6 | AB20: 188.38 | AN20: 27-ene | AO20: 1 | AP20: 29.8
B21: CN004 | C21: 1 | D21: RBWX-10 | E21: 46042 | F21: 27.26 | G21: {=IF( Venta4[[#This Row],[N° Lote]]="", "", IFERROR( INDEX( Mezcla!R:R, _xlfn.XLOOKUP(Venta4[[#This Row],[N° Lote]],Mezcla!R:R,ROW(Mezcla!R:R))+1 ), "" ) )} -> Minera la Cruz Vicente2 1 al 26 | H21: =IF( Venta4[[#This Row],[N° Lote]]="", "", IF( LEFT(Venta4[[#This Row],[N° Lote]],2)="CN", "CERRO NEGRO", IF( AND( ISNUMBER(VALUE(Venta4[[#This Row],[N° Lote]])), LEN(Venta4[[#This Row],[N° Lote]])=4 ), "CEMIN", IF( AND( ISNUMBER(VALUE(Venta4[[#This Row],[N° Lote]])), LEN(Venta4[[#This Row],[N° Lote]])>4 ), "ENAMI", "ORIGEN NO DEFINIDO" ) ) ) ) -> CERRO NEGRO | I21: =IF( Venta4[[#This Row],[N° Lote]]="", "", IF( LEFT(Venta4[[#This Row],[N° Lote]],2)="CN", "Óxido", IF( AND( ISNUMBER(VALUE(Venta4[[#This Row],[N° Lote]])), LEN(Venta4[[#This Row],[N° Lote]])=4 ), "Óxido", IF( AND( ISNUMBER(VALUE(Venta4[[#This Row],[N° Lote]])), LEN(Venta4[[#This Row],[N° Lote]])>4 ), "Sulfuro", "" ) ) ) ) -> Óxido | Z21: 60082 | AA21: 6 | AB21: 188.39 | AN21: 28-ene | AO21: 1 | AP21: 31.29
B22: CN004 | C22: 2 | D22: PYCH-48 | E22: 46042 | F22: 30 | G22: {=IF( Venta4[[#This Row],[N° Lote]]="", "", IFERROR( INDEX( Mezcla!R:R, _xlfn.XLOOKUP(Venta4[[#This Row],[N° Lote]],Mezcla!R:R,ROW(Mezcla!R:R))+1 ), "" ) )} -> Minera la Cruz Vicente2 1 al 26 | H22: =IF( Venta4[[#This Row],[N° Lote]]="", "", IF( LEFT(Venta4[[#This Row],[N° Lote]],2)="CN", "CERRO NEGRO", IF( AND( ISNUMBER(VALUE(Venta4[[#This Row],[N° Lote]])), LEN(Venta4[[#This Row],[N° Lote]])=4 ), "CEMIN", IF( AND( ISNUMBER(VALUE(Venta4[[#This Row],[N° Lote]])), LEN(Venta4[[#This Row],[N° Lote]])>4 ), "ENAMI", "ORIGEN NO DEFINIDO" ) ) ) ) -> CERRO NEGRO | I22: =IF( Venta4[[#This Row],[N° Lote]]="", "", IF( LEFT(Venta4[[#This Row],[N° Lote]],2)="CN", "Óxido", IF( AND( ISNUMBER(VALUE(Venta4[[#This Row],[N° Lote]])), LEN(Venta4[[#This Row],[N° Lote]])=4 ), "Óxido", IF( AND( ISNUMBER(VALUE(Venta4[[#This Row],[N° Lote]])), LEN(Venta4[[#This Row],[N° Lote]])>4 ), "Sulfuro", "" ) ) ) ) -> Óxido | Z22: 60090 | AA22: 6 | AB22: 184.19 | AN22: 29-ene | AO22: 1 | AP22: 32.45
B23: CN004 | C23: 3 | D23: RBWX-10 | E23: 46042 | F23: 25.99 | G23: {=IF( Venta4[[#This Row],[N° Lote]]="", "", IFERROR( INDEX( Mezcla!R:R, _xlfn.XLOOKUP(Venta4[[#This Row],[N° Lote]],Mezcla!R:R,ROW(Mezcla!R:R))+1 ), "" ) )} -> Minera la Cruz Vicente2 1 al 26 | H23: =IF( Venta4[[#This Row],[N° Lote]]="", "", IF( LEFT(Venta4[[#This Row],[N° Lote]],2)="CN", "CERRO NEGRO", IF( AND( ISNUMBER(VALUE(Venta4[[#This Row],[N° Lote]])), LEN(Venta4[[#This Row],[N° Lote]])=4 ), "CEMIN", IF( AND( ISNUMBER(VALUE(Venta4[[#This Row],[N° Lote]])), LEN(Venta4[[#This Row],[N° Lote]])>4 ), "ENAMI", "ORIGEN NO DEFINIDO" ) ) ) ) -> CERRO NEGRO | I23: =IF( Venta4[[#This Row],[N° Lote]]="", "", IF( LEFT(Venta4[[#This Row],[N° Lote]],2)="CN", "Óxido", IF( AND( ISNUMBER(VALUE(Venta4[[#This Row],[N° Lote]])), LEN(Venta4[[#This Row],[N° Lote]])=4 ), "Óxido", IF( AND( ISNUMBER(VALUE(Venta4[[#This Row],[N° Lote]])), LEN(Venta4[[#This Row],[N° Lote]])>4 ), "Sulfuro", "" ) ) ) ) -> Óxido | O23: =+SUM(N18:N23) -> 0 | Z23: 60092 | AA23: 4 | AB23: 125.88 | AN23: feb | AO23: 2 | AP23: 62.93
B24: 1219 | C24: 1 | D24: PYCH-48 | E24: 46043 | F24: 33.43 | G24: {=IF( Venta4[[#This Row],[N° Lote]]="", "", IFERROR( INDEX( Mezcla!R:R, _xlfn.XLOOKUP(Venta4[[#This Row],[N° Lote]],Mezcla!R:R,ROW(Mezcla!R:R))+1 ), "" ) )} -> Mra la cruz Vicente2 | H24: =IF( Venta4[[#This Row],[N° Lote]]="", "", IF( LEFT(Venta4[[#This Row],[N° Lote]],2)="CN", "CERRO NEGRO", IF( AND( ISNUMBER(VALUE(Venta4[[#This Row],[N° Lote]])), LEN(Venta4[[#This Row],[N° Lote]])=4 ), "CEMIN", IF( AND( ISNUMBER(VALUE(Venta4[[#This Row],[N° Lote]])), LEN(Venta4[[#This Row],[N° Lote]])>4 ), "ENAMI", "ORIGEN NO DEFINIDO" ) ) ) ) -> CEMIN | I24: =IF( Venta4[[#This Row],[N° Lote]]="", "", IF( LEFT(Venta4[[#This Row],[N° Lote]],2)="CN", "Óxido", IF( AND( ISNUMBER(VALUE(Venta4[[#This Row],[N° Lote]])), LEN(Venta4[[#This Row],[N° Lote]])=4 ), "Óxido", IF( AND( ISNUMBER(VALUE(Venta4[[#This Row],[N° Lote]])), LEN(Venta4[[#This Row],[N° Lote]])>4 ), "Sulfuro", "" ) ) ) ) -> Óxido | Z24: Total general | AA24: 95 | AB24: 2923.63 | AN24: 09-feb | AO24: 2 | AP24: 62.93
B25: 1219 | C25: 2 | D25: RBWX-10 | E25: 46043 | F25: 28.48 | G25: {=IF( Venta4[[#This Row],[N° Lote]]="", "", IFERROR( INDEX( Mezcla!R:R, _xlfn.XLOOKUP(Venta4[[#This Row],[N° Lote]],Mezcla!R:R,ROW(Mezcla!R:R))+1 ), "" ) )} -> Mra la cruz Vicente2 | H25: =IF( Venta4[[#This Row],[N° Lote]]="", "", IF( LEFT(Venta4[[#This Row],[N° Lote]],2)="CN", "CERRO NEGRO", IF( AND( ISNUMBER(VALUE(Venta4[[#This Row],[N° Lote]])), LEN(Venta4[[#This Row],[N° Lote]])=4 ), "CEMIN", IF( AND( ISNUMBER(VALUE(Venta4[[#This Row],[N° Lote]])), LEN(Venta4[[#This Row],[N° Lote]])>4 ), "ENAMI", "ORIGEN NO DEFINIDO" ) ) ) ) -> CEMIN | I25: =IF( Venta4[[#This Row],[N° Lote]]="", "", IF( LEFT(Venta4[[#This Row],[N° Lote]],2)="CN", "Óxido", IF( AND( ISNUMBER(VALUE(Venta4[[#This Row],[N° Lote]])), LEN(Venta4[[#This Row],[N° Lote]])=4 ), "Óxido", IF( AND( ISNUMBER(VALUE(Venta4[[#This Row],[N° Lote]])), LEN(Venta4[[#This Row],[N° Lote]])>4 ), "Sulfuro", "" ) ) ) ) -> Óxido | AN25: abr | AO25: 42 | AP25: 1353.02
B26: 1219 | C26: 3 | D26: PYCH-48 | E26: 46043 | F26: 34.6 | G26: {=IF( Venta4[[#This Row],[N° Lote]]="", "", IFERROR( INDEX( Mezcla!R:R, _xlfn.XLOOKUP(Venta4[[#This Row],[N° Lote]],Mezcla!R:R,ROW(Mezcla!R:R))+1 ), "" ) )} -> Mra la cruz Vicente2 | H26: =IF( Venta4[[#This Row],[N° Lote]]="", "", IF( LEFT(Venta4[[#This Row],[N° Lote]],2)="CN", "CERRO NEGRO", IF( AND( ISNUMBER(VALUE(Venta4[[#This Row],[N° Lote]])), LEN(Venta4[[#This Row],[N° Lote]])=4 ), "CEMIN", IF( AND( ISNUMBER(VALUE(Venta4[[#This Row],[N° Lote]])), LEN(Venta4[[#This Row],[N° Lote]])>4 ), "ENAMI", "ORIGEN NO DEFINIDO" ) ) ) ) -> CEMIN | I26: =IF( Venta4[[#This Row],[N° Lote]]="", "", IF( LEFT(Venta4[[#This Row],[N° Lote]],2)="CN", "Óxido", IF( AND( ISNUMBER(VALUE(Venta4[[#This Row],[N° Lote]])), LEN(Venta4[[#This Row],[N° Lote]])=4 ), "Óxido", IF( AND( ISNUMBER(VALUE(Venta4[[#This Row],[N° Lote]])), LEN(Venta4[[#This Row],[N° Lote]])>4 ), "Sulfuro", "" ) ) ) ) -> Óxido | AN26: 08-abr | AO26: 2 | AP26: 58.22
B27: 1219 | C27: 4 | D27: RBWX-10 | E27: 46044 | F27: 32.82 | G27: {=IF( Venta4[[#This Row],[N° Lote]]="", "", IFERROR( INDEX( Mezcla!R:R, _xlfn.XLOOKUP(Venta4[[#This Row],[N° Lote]],Mezcla!R:R,ROW(Mezcla!R:R))+1 ), "" ) )} -> Mra la cruz Vicente2 | H27: =IF( Venta4[[#This Row],[N° Lote]]="", "", IF( LEFT(Venta4[[#This Row],[N° Lote]],2)="CN", "CERRO NEGRO", IF( AND( ISNUMBER(VALUE(Venta4[[#This Row],[N° Lote]])), LEN(Venta4[[#This Row],[N° Lote]])=4 ), "CEMIN", IF( AND( ISNUMBER(VALUE(Venta4[[#This Row],[N° Lote]])), LEN(Venta4[[#This Row],[N° Lote]])>4 ), "ENAMI", "ORIGEN NO DEFINIDO" ) ) ) ) -> CEMIN | I27: =IF( Venta4[[#This Row],[N° Lote]]="", "", IF( LEFT(Venta4[[#This Row],[N° Lote]],2)="CN", "Óxido", IF( AND( ISNUMBER(VALUE(Venta4[[#This Row],[N° Lote]])), LEN(Venta4[[#This Row],[N° Lote]])=4 ), "Óxido", IF( AND( ISNUMBER(VALUE(Venta4[[#This Row],[N° Lote]])), LEN(Venta4[[#This Row],[N° Lote]])>4 ), "Sulfuro", "" ) ) ) ) -> Óxido | AN27: 09-abr | AO27: 2 | AP27: 59.99
B28: 10064 | C28: 1 | D28: PYCH-48 | E28: 46044 | F28: 26.61 | G28: {=IF( Venta4[[#This Row],[N° Lote]]="", "", IFERROR( INDEX( Mezcla!R:R, _xlfn.XLOOKUP(Venta4[[#This Row],[N° Lote]],Mezcla!R:R,ROW(Mezcla!R:R))+1 ), "" ) )} -> 3H COPPER El Sauce | H28: =IF( Venta4[[#This Row],[N° Lote]]="", "", IF( LEFT(Venta4[[#This Row],[N° Lote]],2)="CN", "CERRO NEGRO", IF( AND( ISNUMBER(VALUE(Venta4[[#This Row],[N° Lote]])), LEN(Venta4[[#This Row],[N° Lote]])=4 ), "CEMIN", IF( AND( ISNUMBER(VALUE(Venta4[[#This Row],[N° Lote]])), LEN(Venta4[[#This Row],[N° Lote]])>4 ), "ENAMI", "ORIGEN NO DEFINIDO" ) ) ) ) -> ENAMI | I28: =IF( Venta4[[#This Row],[N° Lote]]="", "", IF( LEFT(Venta4[[#This Row],[N° Lote]],2)="CN", "Óxido", IF( AND( ISNUMBER(VALUE(Venta4[[#This Row],[N° Lote]])), LEN(Venta4[[#This Row],[N° Lote]])=4 ), "Óxido", IF( AND( ISNUMBER(VALUE(Venta4[[#This Row],[N° Lote]])), LEN(Venta4[[#This Row],[N° Lote]])>4 ), "Sulfuro", "" ) ) ) ) -> Sulfuro | AN28: 10-abr | AO28: 2 | AP28: 60.03
B29: 1219 | C29: 5 | D29: RBWX-10 | E29: 46045 | F29: 31.81 | G29: {=IF( Venta4[[#This Row],[N° Lote]]="", "", IFERROR( INDEX( Mezcla!R:R, _xlfn.XLOOKUP(Venta4[[#This Row],[N° Lote]],Mezcla!R:R,ROW(Mezcla!R:R))+1 ), "" ) )} -> Mra la cruz Vicente2 | H29: =IF( Venta4[[#This Row],[N° Lote]]="", "", IF( LEFT(Venta4[[#This Row],[N° Lote]],2)="CN", "CERRO NEGRO", IF( AND( ISNUMBER(VALUE(Venta4[[#This Row],[N° Lote]])), LEN(Venta4[[#This Row],[N° Lote]])=4 ), "CEMIN", IF( AND( ISNUMBER(VALUE(Venta4[[#This Row],[N° Lote]])), LEN(Venta4[[#This Row],[N° Lote]])>4 ), "ENAMI", "ORIGEN NO DEFINIDO" ) ) ) ) -> CEMIN | I29: =IF( Venta4[[#This Row],[N° Lote]]="", "", IF( LEFT(Venta4[[#This Row],[N° Lote]],2)="CN", "Óxido", IF( AND( ISNUMBER(VALUE(Venta4[[#This Row],[N° Lote]])), LEN(Venta4[[#This Row],[N° Lote]])=4 ), "Óxido", IF( AND( ISNUMBER(VALUE(Venta4[[#This Row],[N° Lote]])), LEN(Venta4[[#This Row],[N° Lote]])>4 ), "Sulfuro", "" ) ) ) ) -> Óxido | AN29: 13-abr | AO29: 2 | AP29: 68.16
B30: 10064 | C30: 2 | D30: PYCH-48 | E30: 46048 | F30: 29.16 | G30: {=IF( Venta4[[#This Row],[N° Lote]]="", "", IFERROR( INDEX( Mezcla!R:R, _xlfn.XLOOKUP(Venta4[[#This Row],[N° Lote]],Mezcla!R:R,ROW(Mezcla!R:R))+1 ), "" ) )} -> 3H COPPER El Sauce | H30: =IF( Venta4[[#This Row],[N° Lote]]="", "", IF( LEFT(Venta4[[#This Row],[N° Lote]],2)="CN", "CERRO NEGRO", IF( AND( ISNUMBER(VALUE(Venta4[[#This Row],[N° Lote]])), LEN(Venta4[[#This Row],[N° Lote]])=4 ), "CEMIN", IF( AND( ISNUMBER(VALUE(Venta4[[#This Row],[N° Lote]])), LEN(Venta4[[#This Row],[N° Lote]])>4 ), "ENAMI", "ORIGEN NO DEFINIDO" ) ) ) ) -> ENAMI | I30: =IF( Venta4[[#This Row],[N° Lote]]="", "", IF( LEFT(Venta4[[#This Row],[N° Lote]],2)="CN", "Óxido", IF( AND( ISNUMBER(VALUE(Venta4[[#This Row],[N° Lote]])), LEN(Venta4[[#This Row],[N° Lote]])=4 ), "Óxido", IF( AND( ISNUMBER(VALUE(Venta4[[#This Row],[N° Lote]])), LEN(Venta4[[#This Row],[N° Lote]])>4 ), "Sulfuro", "" ) ) ) ) -> Sulfuro | AN30: 14-abr | AO30: 1 | AP30: 30.37
B31: 10082 | C31: 1 | D31: PYCH-48 | E31: 46049 | F31: 29.8 | G31: {=IF( Venta4[[#This Row],[N° Lote]]="", "", IFERROR( INDEX( Mezcla!R:R, _xlfn.XLOOKUP(Venta4[[#This Row],[N° Lote]],Mezcla!R:R,ROW(Mezcla!R:R))+1 ), "" ) )} -> 3H COPPER El Sauce | H31: =IF( Venta4[[#This Row],[N° Lote]]="", "", IF( LEFT(Venta4[[#This Row],[N° Lote]],2)="CN", "CERRO NEGRO", IF( AND( ISNUMBER(VALUE(Venta4[[#This Row],[N° Lote]])), LEN(Venta4[[#This Row],[N° Lote]])=4 ), "CEMIN", IF( AND( ISNUMBER(VALUE(Venta4[[#This Row],[N° Lote]])), LEN(Venta4[[#This Row],[N° Lote]])>4 ), "ENAMI", "ORIGEN NO DEFINIDO" ) ) ) ) -> ENAMI | I31: =IF( Venta4[[#This Row],[N° Lote]]="", "", IF( LEFT(Venta4[[#This Row],[N° Lote]],2)="CN", "Óxido", IF( AND( ISNUMBER(VALUE(Venta4[[#This Row],[N° Lote]])), LEN(Venta4[[#This Row],[N° Lote]])=4 ), "Óxido", IF( AND( ISNUMBER(VALUE(Venta4[[#This Row],[N° Lote]])), LEN(Venta4[[#This Row],[N° Lote]])>4 ), "Sulfuro", "" ) ) ) ) -> Sulfuro | AN31: 15-abr | AO31: 1 | AP31: 36.64
B32: 10082 | C32: 2 | D32: RBWX-10 | E32: 46050 | F32: 31.29 | G32: {=IF( Venta4[[#This Row],[N° Lote]]="", "", IFERROR( INDEX( Mezcla!R:R, _xlfn.XLOOKUP(Venta4[[#This Row],[N° Lote]],Mezcla!R:R,ROW(Mezcla!R:R))+1 ), "" ) )} -> 3H COPPER El Sauce | H32: =IF( Venta4[[#This Row],[N° Lote]]="", "", IF( LEFT(Venta4[[#This Row],[N° Lote]],2)="CN", "CERRO NEGRO", IF( AND( ISNUMBER(VALUE(Venta4[[#This Row],[N° Lote]])), LEN(Venta4[[#This Row],[N° Lote]])=4 ), "CEMIN", IF( AND( ISNUMBER(VALUE(Venta4[[#This Row],[N° Lote]])), LEN(Venta4[[#This Row],[N° Lote]])>4 ), "ENAMI", "ORIGEN NO DEFINIDO" ) ) ) ) -> ENAMI | I32: =IF( Venta4[[#This Row],[N° Lote]]="", "", IF( LEFT(Venta4[[#This Row],[N° Lote]],2)="CN", "Óxido", IF( AND( ISNUMBER(VALUE(Venta4[[#This Row],[N° Lote]])), LEN(Venta4[[#This Row],[N° Lote]])=4 ), "Óxido", IF( AND( ISNUMBER(VALUE(Venta4[[#This Row],[N° Lote]])), LEN(Venta4[[#This Row],[N° Lote]])>4 ), "Sulfuro", "" ) ) ) ) -> Sulfuro | AN32: 16-abr | AO32: 2 | AP32: 60.29
B33: 10082 | C33: 3 | D33: PYCH-48 | E33: 46051 | F33: 32.45 | G33: {=IF( Venta4[[#This Row],[N° Lote]]="", "", IFERROR( INDEX( Mezcla!R:R, _xlfn.XLOOKUP(Venta4[[#This Row],[N° Lote]],Mezcla!R:R,ROW(Mezcla!R:R))+1 ), "" ) )} -> 3H COPPER El Sauce | H33: =IF( Venta4[[#This Row],[N° Lote]]="", "", IF( LEFT(Venta4[[#This Row],[N° Lote]],2)="CN", "CERRO NEGRO", IF( AND( ISNUMBER(VALUE(Venta4[[#This Row],[N° Lote]])), LEN(Venta4[[#This Row],[N° Lote]])=4 ), "CEMIN", IF( AND( ISNUMBER(VALUE(Venta4[[#This Row],[N° Lote]])), LEN(Venta4[[#This Row],[N° Lote]])>4 ), "ENAMI", "ORIGEN NO DEFINIDO" ) ) ) ) -> ENAMI | I33: =IF( Venta4[[#This Row],[N° Lote]]="", "", IF( LEFT(Venta4[[#This Row],[N° Lote]],2)="CN", "Óxido", IF( AND( ISNUMBER(VALUE(Venta4[[#This Row],[N° Lote]])), LEN(Venta4[[#This Row],[N° Lote]])=4 ), "Óxido", IF( AND( ISNUMBER(VALUE(Venta4[[#This Row],[N° Lote]])), LEN(Venta4[[#This Row],[N° Lote]])>4 ), "Sulfuro", "" ) ) ) ) -> Sulfuro | AN33: 17-abr | AO33: 2 | AP33: 64.93
B34: 20026 | C34: 1 | D34: PYCH-48 | E34: 46062 | F34: 29.39 | G34: {=IF( Venta4[[#This Row],[N° Lote]]="", "", IFERROR( INDEX( Mezcla!R:R, _xlfn.XLOOKUP(Venta4[[#This Row],[N° Lote]],Mezcla!R:R,ROW(Mezcla!R:R))+1 ), "" ) )} -> 3H COPPER El Sauce | H34: =IF( Venta4[[#This Row],[N° Lote]]="", "", IF( LEFT(Venta4[[#This Row],[N° Lote]],2)="CN", "CERRO NEGRO", IF( AND( ISNUMBER(VALUE(Venta4[[#This Row],[N° Lote]])), LEN(Venta4[[#This Row],[N° Lote]])=4 ), "CEMIN", IF( AND( ISNUMBER(VALUE(Venta4[[#This Row],[N° Lote]])), LEN(Venta4[[#This Row],[N° Lote]])>4 ), "ENAMI", "ORIGEN NO DEFINIDO" ) ) ) ) -> ENAMI | I34: =IF( Venta4[[#This Row],[N° Lote]]="", "", IF( LEFT(Venta4[[#This Row],[N° Lote]],2)="CN", "Óxido", IF( AND( ISNUMBER(VALUE(Venta4[[#This Row],[N° Lote]])), LEN(Venta4[[#This Row],[N° Lote]])=4 ), "Óxido", IF( AND( ISNUMBER(VALUE(Venta4[[#This Row],[N° Lote]])), LEN(Venta4[[#This Row],[N° Lote]])>4 ), "Sulfuro", "" ) ) ) ) -> Sulfuro | AN34: 20-abr | AO34: 4 | AP34: 125.37
B35: 20026 | C35: 2 | D35: RBWX-10 | E35: 46062 | F35: 33.54 | G35: {=IF( Venta4[[#This Row],[N° Lote]]="", "", IFERROR( INDEX( Mezcla!R:R, _xlfn.XLOOKUP(Venta4[[#This Row],[N° Lote]],Mezcla!R:R,ROW(Mezcla!R:R))+1 ), "" ) )} -> 3H COPPER El Sauce | H35: =IF( Venta4[[#This Row],[N° Lote]]="", "", IF( LEFT(Venta4[[#This Row],[N° Lote]],2)="CN", "CERRO NEGRO", IF( AND( ISNUMBER(VALUE(Venta4[[#This Row],[N° Lote]])), LEN(Venta4[[#This Row],[N° Lote]])=4 ), "CEMIN", IF( AND( ISNUMBER(VALUE(Venta4[[#This Row],[N° Lote]])), LEN(Venta4[[#This Row],[N° Lote]])>4 ), "ENAMI", "ORIGEN NO DEFINIDO" ) ) ) ) -> ENAMI | I35: =IF( Venta4[[#This Row],[N° Lote]]="", "", IF( LEFT(Venta4[[#This Row],[N° Lote]],2)="CN", "Óxido", IF( AND( ISNUMBER(VALUE(Venta4[[#This Row],[N° Lote]])), LEN(Venta4[[#This Row],[N° Lote]])=4 ), "Óxido", IF( AND( ISNUMBER(VALUE(Venta4[[#This Row],[N° Lote]])), LEN(Venta4[[#This Row],[N° Lote]])>4 ), "Sulfuro", "" ) ) ) ) -> Sulfuro | AN35: 21-abr | AO35: 2 | AP35: 68.28
A36: ABRIL | B36: 40018 | C36: 1 | D36: PYCH-48 | E36: 46120 | F36: 30.52 | G36: {=IF( Venta4[[#This Row],[N° Lote]]="", "", IFERROR( INDEX( Mezcla!T:T, _xlfn.XLOOKUP(Venta4[[#This Row],[N° Lote]],Mezcla!T:T,ROW(Mezcla!T:T))+1 ), "" ) )} -> Minera la Cruz | H36: =IF( Venta4[[#This Row],[N° Lote]]="", "", IF( LEFT(Venta4[[#This Row],[N° Lote]],2)="CN", "CERRO NEGRO", IF( AND( ISNUMBER(VALUE(Venta4[[#This Row],[N° Lote]])), LEN(Venta4[[#This Row],[N° Lote]])=4 ), "CEMIN", IF( AND( ISNUMBER(VALUE(Venta4[[#This Row],[N° Lote]])), LEN(Venta4[[#This Row],[N° Lote]])>4 ), "ENAMI", "ORIGEN NO DEFINIDO" ) ) ) ) -> ENAMI | I36: =IF( Venta4[[#This Row],[N° Lote]]="", "", IF( LEFT(Venta4[[#This Row],[N° Lote]],2)="CN", "Óxido", IF( AND( ISNUMBER(VALUE(Venta4[[#This Row],[N° Lote]])), LEN(Venta4[[#This Row],[N° Lote]])=4 ), "Óxido", IF( AND( ISNUMBER(VALUE(Venta4[[#This Row],[N° Lote]])), LEN(Venta4[[#This Row],[N° Lote]])>4 ), "Sulfuro", "" ) ) ) ) -> Sulfuro | AN36: 22-abr | AO36: 4 | AP36: 136.78
B37: 40018 | C37: 2 | D37: RBWX-10 | E37: 46120 | F37: 27.7 | G37: {=IF( Venta4[[#This Row],[N° Lote]]="", "", IFERROR( INDEX( Mezcla!T:T, _xlfn.XLOOKUP(Venta4[[#This Row],[N° Lote]],Mezcla!T:T,ROW(Mezcla!T:T))+1 ), "" ) )} -> Minera la Cruz | H37: =IF( Venta4[[#This Row],[N° Lote]]="", "", IF( LEFT(Venta4[[#This Row],[N° Lote]],2)="CN", "CERRO NEGRO", IF( AND( ISNUMBER(VALUE(Venta4[[#This Row],[N° Lote]])), LEN(Venta4[[#This Row],[N° Lote]])=4 ), "CEMIN", IF( AND( ISNUMBER(VALUE(Venta4[[#This Row],[N° Lote]])), LEN(Venta4[[#This Row],[N° Lote]])>4 ), "ENAMI", "ORIGEN NO DEFINIDO" ) ) ) ) -> ENAMI | I37: =IF( Venta4[[#This Row],[N° Lote]]="", "", IF( LEFT(Venta4[[#This Row],[N° Lote]],2)="CN", "Óxido", IF( AND( ISNUMBER(VALUE(Venta4[[#This Row],[N° Lote]])), LEN(Venta4[[#This Row],[N° Lote]])=4 ), "Óxido", IF( AND( ISNUMBER(VALUE(Venta4[[#This Row],[N° Lote]])), LEN(Venta4[[#This Row],[N° Lote]])>4 ), "Sulfuro", "" ) ) ) ) -> Sulfuro | AN37: 23-abr | AO37: 3 | AP37: 90.18
B38: 40018 | C38: 3 | D38: PYCH-48 | E38: 46121 | F38: 30.63 | G38: {=IF( Venta4[[#This Row],[N° Lote]]="", "", IFERROR( INDEX( Mezcla!T:T, _xlfn.XLOOKUP(Venta4[[#This Row],[N° Lote]],Mezcla!T:T,ROW(Mezcla!T:T))+1 ), "" ) )} -> Minera la Cruz | H38: =IF( Venta4[[#This Row],[N° Lote]]="", "", IF( LEFT(Venta4[[#This Row],[N° Lote]],2)="CN", "CERRO NEGRO", IF( AND( ISNUMBER(VALUE(Venta4[[#This Row],[N° Lote]])), LEN(Venta4[[#This Row],[N° Lote]])=4 ), "CEMIN", IF( AND( ISNUMBER(VALUE(Venta4[[#This Row],[N° Lote]])), LEN(Venta4[[#This Row],[N° Lote]])>4 ), "ENAMI", "ORIGEN NO DEFINIDO" ) ) ) ) -> ENAMI | I38: =IF( Venta4[[#This Row],[N° Lote]]="", "", IF( LEFT(Venta4[[#This Row],[N° Lote]],2)="CN", "Óxido", IF( AND( ISNUMBER(VALUE(Venta4[[#This Row],[N° Lote]])), LEN(Venta4[[#This Row],[N° Lote]])=4 ), "Óxido", IF( AND( ISNUMBER(VALUE(Venta4[[#This Row],[N° Lote]])), LEN(Venta4[[#This Row],[N° Lote]])>4 ), "Sulfuro", "" ) ) ) ) -> Sulfuro | AN38: 24-abr | AO38: 4 | AP38: 132.52
B39: 40018 | C39: 4 | D39: RBWX-10 | E39: 46121 | F39: 29.36 | G39: {=IF( Venta4[[#This Row],[N° Lote]]="", "", IFERROR( INDEX( Mezcla!T:T, _xlfn.XLOOKUP(Venta4[[#This Row],[N° Lote]],Mezcla!T:T,ROW(Mezcla!T:T))+1 ), "" ) )} -> Minera la Cruz | H39: =IF( Venta4[[#This Row],[N° Lote]]="", "", IF( LEFT(Venta4[[#This Row],[N° Lote]],2)="CN", "CERRO NEGRO", IF( AND( ISNUMBER(VALUE(Venta4[[#This Row],[N° Lote]])), LEN(Venta4[[#This Row],[N° Lote]])=4 ), "CEMIN", IF( AND( ISNUMBER(VALUE(Venta4[[#This Row],[N° Lote]])), LEN(Venta4[[#This Row],[N° Lote]])>4 ), "ENAMI", "ORIGEN NO DEFINIDO" ) ) ) ) -> ENAMI | I39: =IF( Venta4[[#This Row],[N° Lote]]="", "", IF( LEFT(Venta4[[#This Row],[N° Lote]],2)="CN", "Óxido", IF( AND( ISNUMBER(VALUE(Venta4[[#This Row],[N° Lote]])), LEN(Venta4[[#This Row],[N° Lote]])=4 ), "Óxido", IF( AND( ISNUMBER(VALUE(Venta4[[#This Row],[N° Lote]])), LEN(Venta4[[#This Row],[N° Lote]])>4 ), "Sulfuro", "" ) ) ) ) -> Sulfuro | AN39: 25-abr | AO39: 2 | AP39: 64.63
B40: 40030 | C40: 1 | D40: PYCH-48 | E40: 46122 | F40: 31.09 | G40: {=IF( Venta4[[#This Row],[N° Lote]]="", "", IFERROR( INDEX( Mezcla!T:T, _xlfn.XLOOKUP(Venta4[[#This Row],[N° Lote]],Mezcla!T:T,ROW(Mezcla!T:T))+1 ), "" ) )} -> Minera la Cruz | H40: =IF( Venta4[[#This Row],[N° Lote]]="", "", IF( LEFT(Venta4[[#This Row],[N° Lote]],2)="CN", "CERRO NEGRO", IF( AND( ISNUMBER(VALUE(Venta4[[#This Row],[N° Lote]])), LEN(Venta4[[#This Row],[N° Lote]])=4 ), "CEMIN", IF( AND( ISNUMBER(VALUE(Venta4[[#This Row],[N° Lote]])), LEN(Venta4[[#This Row],[N° Lote]])>4 ), "ENAMI", "ORIGEN NO DEFINIDO" ) ) ) ) -> ENAMI | I40: =IF( Venta4[[#This Row],[N° Lote]]="", "", IF( LEFT(Venta4[[#This Row],[N° Lote]],2)="CN", "Óxido", IF( AND( ISNUMBER(VALUE(Venta4[[#This Row],[N° Lote]])), LEN(Venta4[[#This Row],[N° Lote]])=4 ), "Óxido", IF( AND( ISNUMBER(VALUE(Venta4[[#This Row],[N° Lote]])), LEN(Venta4[[#This Row],[N° Lote]])>4 ), "Sulfuro", "" ) ) ) ) -> Sulfuro | AN40: 27-abr | AO40: 3 | AP40: 94.21
B41: 40030 | C41: 2 | D41: RBWX-10 | E41: 46122 | F41: 28.94 | G41: {=IF( Venta4[[#This Row],[N° Lote]]="", "", IFERROR( INDEX( Mezcla!T:T, _xlfn.XLOOKUP(Venta4[[#This Row],[N° Lote]],Mezcla!T:T,ROW(Mezcla!T:T))+1 ), "" ) )} -> Minera la Cruz | H41: =IF( Venta4[[#This Row],[N° Lote]]="", "", IF( LEFT(Venta4[[#This Row],[N° Lote]],2)="CN", "CERRO NEGRO", IF( AND( ISNUMBER(VALUE(Venta4[[#This Row],[N° Lote]])), LEN(Venta4[[#This Row],[N° Lote]])=4 ), "CEMIN", IF( AND( ISNUMBER(VALUE(Venta4[[#This Row],[N° Lote]])), LEN(Venta4[[#This Row],[N° Lote]])>4 ), "ENAMI", "ORIGEN NO DEFINIDO" ) ) ) ) -> ENAMI | I41: =IF( Venta4[[#This Row],[N° Lote]]="", "", IF( LEFT(Venta4[[#This Row],[N° Lote]],2)="CN", "Óxido", IF( AND( ISNUMBER(VALUE(Venta4[[#This Row],[N° Lote]])), LEN(Venta4[[#This Row],[N° Lote]])=4 ), "Óxido", IF( AND( ISNUMBER(VALUE(Venta4[[#This Row],[N° Lote]])), LEN(Venta4[[#This Row],[N° Lote]])>4 ), "Sulfuro", "" ) ) ) ) -> Sulfuro | AN41: 28-abr | AO41: 3 | AP41: 103.07
...

Sheet Mezcla
A2: Enero | B2: 2026 | C2: - | D2: - | E2: - | F2: - | G2: - | I2: - | Q2: - | R2: - | S2: - | T2: - | U2: - | V2: - | W2: - | X2: - | Y2: - | Z2: - | AA2: - | AB2: - | AC2: - | AD2: - | AE2: - | AF2: - | AG2: - | AH2: - | AI2: - | AJ2: - | AK2: - | AL2: - | AM2: - | AN2: - | AO2: - | AP2: - | AQ2: - | AR2: - | AS2: - | AT2: - | AU2: - | AV2: - | AW2: - | AX2: - | AY2: - | AZ2: - | BA2: - | BB2: -
I4: CN001 | J4: ACOPIO | K4: TON | L4: LEY DUMP | M4: LEY VISUAL | N4: LEY LOTE | R4: CERRO NEGRO | AH4: =+I4 -> CN001 | AI4: Cui
B5: fecha | C5: (Varios elementos) | H5: 34 | I5: =IF(H5="", IFERROR(MATCH("**", B:B, 0), ""), IFERROR(MATCH("* "&H5&" *", B:B, 0), "") ) -> 41 | J5: {=INDIRECT("B" & I5)} -> NIVEL 789 REC PM 34 29-12-2025 | K5: =INDEX(D:D, MATCH(J5, $B:$B, 0)) -> 3.4 | L5: =INDEX(E:E, MATCH(J5, $B:$B, 0))*0.9 -> 0.02484 | M5: =INDEX(F:F, MATCH(J5, $B:$B, 0)) -> 0 | N5: =+IF(L5=0,M5*0.9,L5*0.9) -> 0.022356 | O5: =+IF(L5=0,"-","Dump") -> Dump | P5: =+K5/5.6 -> 0.60714286 | AH5: =+K60-SUMIF(AB:AB, AH4, Y:Y) -> 77.59 | AI5: =+N60 -> 0.014050508 | AJ5: =COUNTIF(AB:AB, AH4) -> 4
H6: 35 | I6: =IF(H6="", IFERROR(MATCH("**", B:B, 0), ""), IFERROR(MATCH("* "&H6&" *", B:B, 0), "") ) -> 42 | J6: {=INDIRECT("B" & I6)} -> NIVEL 789 REC PM 35 29-12-2025 | K6: =INDEX(D:D, MATCH(J6, $B:$B, 0)) -> 3.4 | L6: =INDEX(E:E, MATCH(J6, $B:$B, 0))*0.9 -> 0.01845 | M6: =INDEX(F:F, MATCH(J6, $B:$B, 0)) -> 0 | N6: =+IF(L6=0,M6*0.9,L6*0.9) -> 0.016605 | O6: =+IF(L6=0,"-","Dump") -> Dump | P6: =+K6/5.6 -> 0.60714286 | R6: N°Lote | S6: Camionada | T6: Ticket | U6: Patente | V6: Fecha Despacho | W6: Fecha Recepción | X6: Hora | Y6: Peso | Z6: Ley mezcla | AA6: Ley Visual | AB6: Origen | AC6: Ley Lab Camion | AD6: Diferencia | AE6: % Error
B7: ACOPIOS | C7: DUMPADAS | D7: TON. | E7: ley Cup | F7: Promedio de Ley Visual | H7: 36 | I7: =IF(H7="", IFERROR(MATCH("**", B:B, 0), ""), IFERROR(MATCH("* "&H7&" *", B:B, 0), "") ) -> 43 | J7: {=INDIRECT("B" & I7)} -> NIVEL 789 REC PM 36 29-12-2025 | K7: =INDEX(D:D, MATCH(J7, $B:$B, 0)) -> 3.4 | L7: =INDEX(E:E, MATCH(J7, $B:$B, 0))*0.9 -> 0.01782 | M7: =INDEX(F:F, MATCH(J7, $B:$B, 0)) -> 0 | N7: =+IF(L7=0,M7*0.9,L7*0.9) -> 0.016038 | O7: =+IF(L7=0,"-","Dump") -> Dump | P7: =+K7/5.6 -> 0.60714286 | R7: CN001 | S7: 1 | U7: PYCH-48 | V7: 46035 | W7: 46035 | Y7: 27.35 | Z7: =+L61 -> 0.017346306 | AA7: =+M60 -> 0 | AB7: =+I4 -> CN001 | AD7: =+AC18-Z18 -> -0.01792905 | AE7: =+(AC18-Z18)/Z18 -> -1
B8: NIVEL 970 SELLO AM 1 24-12-2025 | C8: 1 | D8: 3.5 | E8: 0.012 | H8: 37 | I8: =IF(H8="", IFERROR(MATCH("**", B:B, 0), ""), IFERROR(MATCH("* "&H8&" *", B:B, 0), "") ) -> 44 | J8: {=INDIRECT("B" & I8)} -> NIVEL 1018 FRENTE AM 37 30-12-2025 | K8: =INDEX(D:D, MATCH(J8, $B:$B, 0)) -> 3.5 | L8: =INDEX(E:E, MATCH(J8, $B:$B, 0))*0.9 -> 0.02061 | M8: =INDEX(F:F, MATCH(J8, $B:$B, 0)) -> 0 | N8: =+IF(L8=0,M8*0.9,L8*0.9) -> 0.018549 | O8: =+IF(L8=0,"-","Dump") -> Dump | P8: =+K8/5.6 -> 0.625 | R8: 3H COPPER EL SAUCE 1 AL 5 | S8: 2 | U8: JKDK-25 | V8: 46035 | W8: 46035 | Y8: 30.41 | Z8: =+L61 -> 0.017346306 | AA8: =+M60 -> 0 | AB8: =+I4 -> CN001
B9: NIVEL 970 SELLO AM 2 24-12-2025 | C9: 1 | D9: 3.5 | E9: 0.012 | H9: 38 | I9: =IF(H9="", IFERROR(MATCH("**", B:B, 0), ""), IFERROR(MATCH("* "&H9&" *", B:B, 0), "") ) -> 45 | J9: {=INDIRECT("B" & I9)} -> NIVEL 1018 FRENTE AM 38 30-12-2025 | K9: =INDEX(D:D, MATCH(J9, $B:$B, 0)) -> 3.5 | L9: =INDEX(E:E, MATCH(J9, $B:$B, 0))*0.9 -> 0.01305 | M9: =INDEX(F:F, MATCH(J9, $B:$B, 0)) -> 0 | N9: =+IF(L9=0,M9*0.9,L9*0.9) -> 0.011745 | O9: =+IF(L9=0,"-","Dump") -> Dump | P9: =+K9/5.6 -> 0.625 | S9: 3 | U9: LCGZ-26 | V9: 46035 | W9: 46035 | Y9: 27.69 | Z9: =+L61 -> 0.017346306 | AA9: =+M60 -> 0 | AB9: =+I4 -> CN001
B10: NIVEL 970 SELLO AM 3 24-12-2025 | C10: 1 | D10: 3.5 | E10: 0.012 | H10: 39 | I10: =IF(H10="", IFERROR(MATCH("**", B:B, 0), ""), IFERROR(MATCH("* "&H10&" *", B:B, 0), "") ) -> 46 | J10: {=INDIRECT("B" & I10)} -> NIVEL 1018 FRENTE AM 39 30-12-2025 | K10: =INDEX(D:D, MATCH(J10, $B:$B, 0)) -> 3.5 | L10: =INDEX(E:E, MATCH(J10, $B:$B, 0))*0.9 -> 0.02268 | M10: =INDEX(F:F, MATCH(J10, $B:$B, 0)) -> 0 | N10: =+IF(L10=0,M10*0.9,L10*0.9) -> 0.020412 | O10: =+IF(L10=0,"-","Dump") -> Dump | P10: =+K10/5.6 -> 0.625 | S10: 4 | U10: PYCH-48 | V10: 46036 | W10: 46036 | Y10: 29.16 | Z10: =+L61 -> 0.017346306 | AA10: =+M60 -> 0 | AB10: =+I4 -> CN001
B11: NIVEL 970 SELLO AM 4 24-12-2025 | C11: 1 | D11: 3.5 | E11: 0.012 | H11: 40 | I11: =IF(H11="", IFERROR(MATCH("**", B:B, 0), ""), IFERROR(MATCH("* "&H11&" *", B:B, 0), "") ) -> 47 | J11: {=INDIRECT("B" & I11)} -> NIVEL 1018 FRENTE AM 40 30-12-2025 | K11: =INDEX(D:D, MATCH(J11, $B:$B, 0)) -> 3.5 | L11: =INDEX(E:E, MATCH(J11, $B:$B, 0))*0.9 -> 0.0099 | M11: =INDEX(F:F, MATCH(J11, $B:$B, 0)) -> 0 | N11: =+IF(L11=0,M11*0.9,L11*0.9) -> 0.00891 | O11: =+IF(L11=0,"-","Dump") -> Dump | P11: =+K11/5.6 -> 0.625 | S11: 5 | U11: LCGZ-26 | V11: 46036 | W11: 46036 | Y11: 29.22 | Z11: =+L100 -> 0.019078788 | AA11: =+M99 -> 0 | AB11: =+I65 -> CN002
B12: NIVEL 970 SELLO AM 5 24-12-2025 | C12: 1 | D12: 3.5 | E12: 0.012 | H12: 41 | I12: =IF(H12="", IFERROR(MATCH("**", B:B, 0), ""), IFERROR(MATCH("* "&H12&" *", B:B, 0), "") ) -> 48 | J12: {=INDIRECT("B" & I12)} -> NIVEL 1018 FRENTE AM 41 30-12-2025 | K12: =INDEX(D:D, MATCH(J12, $B:$B, 0)) -> 3.5 | L12: =INDEX(E:E, MATCH(J12, $B:$B, 0))*0.9 -> 0.01368 | M12: =INDEX(F:F, MATCH(J12, $B:$B, 0)) -> 0 | N12: =+IF(L12=0,M12*0.9,L12*0.9) -> 0.012312 | O12: =+IF(L12=0,"-","Dump") -> Dump | P12: =+K12/5.6 -> 0.625 | S12: 6 | U12: RBWX-10 | V12: 46036 | W12: 46036 | Y12: 28.87 | Z12: =+L100 -> 0.019078788 | AA12: =+M99 -> 0 | AB12: =+I65 -> CN002
B13: NIVEL 970 SELLO AM 6 24-12-2025 | C13: 1 | D13: 3.5 | E13: 0.012 | H13: 42 | I13: =IF(H13="", IFERROR(MATCH("**", B:B, 0), ""), IFERROR(MATCH("* "&H13&" *", B:B, 0), "") ) -> 49 | J13: {=INDIRECT("B" & I13)} -> NIVEL 1018 FRENTE AM 42 30-12-2025 | K13: =INDEX(D:D, MATCH(J13, $B:$B, 0)) -> 3.5 | L13: =INDEX(E:E, MATCH(J13, $B:$B, 0))*0.9 -> 0.01701 | M13: =INDEX(F:F, MATCH(J13, $B:$B, 0)) -> 0 | N13: =+IF(L13=0,M13*0.9,L13*0.9) -> 0.015309 | O13: =+IF(L13=0,"-","Dump") -> Dump | P13: =+K13/5.6 -> 0.625 | S13: 7
B14: NIVEL 970 SELLO AM 7 26-12-2025 | C14: 1 | D14: 3.5 | E14: 0.0163 | H14: 53 | I14: =IF(H14="", IFERROR(MATCH("**", B:B, 0), ""), IFERROR(MATCH("* "&H14&" *", B:B, 0), "") ) -> 60 | J14: {=INDIRECT("B" & I14)} -> NIVEL 1018 FRENTE AM 53 30-12-2025 | K14: =INDEX(D:D, MATCH(J14, $B:$B, 0)) -> 3.5 | L14: =INDEX(E:E, MATCH(J14, $B:$B, 0))*0.9 -> 0.01062 | M14: =INDEX(F:F, MATCH(J14, $B:$B, 0)) -> 0 | N14: =+IF(L14=0,M14*0.9,L14*0.9) -> 0.009558 | O14: =+IF(L14=0,"-","Dump") -> Dump | P14: =+K14/5.6 -> 0.625 | S14: 8
B15: NIVEL 970 SELLO AM 8 26-12-2025 | C15: 1 | D15: 3.5 | E15: 0.0163 | H15: 54 | I15: =IF(H15="", IFERROR(MATCH("**", B:B, 0), ""), IFERROR(MATCH("* "&H15&" *", B:B, 0), "") ) -> 61 | J15: {=INDIRECT("B" & I15)} -> NIVEL 1018 FRENTE AM 54 30-12-2025 | K15: =INDEX(D:D, MATCH(J15, $B:$B, 0)) -> 3.5 | L15: =INDEX(E:E, MATCH(J15, $B:$B, 0))*0.9 -> 0.01269 | M15: =INDEX(F:F, MATCH(J15, $B:$B, 0)) -> 0 | N15: =+IF(L15=0,M15*0.9,L15*0.9) -> 0.011421 | O15: =+IF(L15=0,"-","Dump") -> Dump | P15: =+K15/5.6 -> 0.625 | S15: 9
B16: NIVEL 970 SELLO AM 9 26-12-2025 | C16: 1 | D16: 3.5 | E16: 0.0163 | H16: 55 | I16: =IF(H16="", IFERROR(MATCH("**", B:B, 0), ""), IFERROR(MATCH("* "&H16&" *", B:B, 0), "") ) -> 62 | J16: {=INDIRECT("B" & I16)} -> NIVEL 1018 FRENTE AM 55 30-12-2025 | K16: =INDEX(D:D, MATCH(J16, $B:$B, 0)) -> 3.5 | L16: =INDEX(E:E, MATCH(J16, $B:$B, 0))*0.9 -> 0.01359 | M16: =INDEX(F:F, MATCH(J16, $B:$B, 0)) -> 0 | N16: =+IF(L16=0,M16*0.9,L16*0.9) -> 0.012231 | O16: =+IF(L16=0,"-","Dump") -> Dump | P16: =+K16/5.6 -> 0.625 | S16: 10
B17: NIVEL 970 SELLO AM 10 26-12-2025 | C17: 1 | D17: 3.5 | E17: 0.0163 | H17: 56 | I17: =IF(H17="", IFERROR(MATCH("**", B:B, 0), ""), IFERROR(MATCH("* "&H17&" *", B:B, 0), "") ) -> 63 | J17: {=INDIRECT("B" & I17)} -> NIVEL 1018 FRENTE AM 56 30-12-2025 | K17: =INDEX(D:D, MATCH(J17, $B:$B, 0)) -> 3.5 | L17: =INDEX(E:E, MATCH(J17, $B:$B, 0))*0.9 -> 0.01062 | M17: =INDEX(F:F, MATCH(J17, $B:$B, 0)) -> 0 | N17: =+IF(L17=0,M17*0.9,L17*0.9) -> 0.009558 | O17: =+IF(L17=0,"-","Dump") -> Dump | P17: =+K17/5.6 -> 0.625 | S17: 11
B18: NIVEL 970 SELLO AM 11 26-12-2025 | C18: 1 | D18: 3.5 | E18: 0.0163 | H18: 57 | I18: =IF(H18="", IFERROR(MATCH("**", B:B, 0), ""), IFERROR(MATCH("* "&H18&" *", B:B, 0), "") ) -> 64 | J18: {=INDIRECT("B" & I18)} -> NIVEL 1018 FRENTE AM 57 30-12-2025 | K18: =INDEX(D:D, MATCH(J18, $B:$B, 0)) -> 3.5 | L18: =INDEX(E:E, MATCH(J18, $B:$B, 0))*0.9 -> 0.0072 | M18: =INDEX(F:F, MATCH(J18, $B:$B, 0)) -> 0 | N18: =+IF(L18=0,M18*0.9,L18*0.9) -> 0.00648 | O18: =+IF(L18=0,"-","Dump") -> Dump | P18: =+K18/5.6 -> 0.625 | Y18: =SUM(Y7:Y17) -> 172.7 | Z18: =+SUMPRODUCT(Y7:Y17,Z7:Z17)/Y18 -> 0.01792905 | AA18: =+SUMPRODUCT(Y7:Y17,AA7:AA17)/Y18 -> 0 | AC18: 0
B19: NIVEL 970 SELLO AM 12 26-12-2025 | C19: 1 | D19: 3.5 | E19: 0.0163 | H19: 58 | I19: =IF(H19="", IFERROR(MATCH("**", B:B, 0), ""), IFERROR(MATCH("* "&H19&" *", B:B, 0), "") ) -> 65 | J19: {=INDIRECT("B" & I19)} -> NIVEL 1018 FRENTE AM 58 30-12-2025 | K19: =INDEX(D:D, MATCH(J19, $B:$B, 0)) -> 3.5 | L19: =INDEX(E:E, MATCH(J19, $B:$B, 0))*0.9 -> 0.01143 | M19: =INDEX(F:F, MATCH(J19, $B:$B, 0)) -> 0 | N19: =+IF(L19=0,M19*0.9,L19*0.9) -> 0.010287 | O19: =+IF(L19=0,"-","Dump") -> Dump | P19: =+K19/5.6 -> 0.625
B20: NIVEL 1018 REC AM 13 27-12-2025 | C20: 1 | D20: 3.5 | E20: 0.02 | H20: 59 | I20: =IF(H20="", IFERROR(MATCH("**", B:B, 0), ""), IFERROR(MATCH("* "&H20&" *", B:B, 0), "") ) -> 66 | J20: {=INDIRECT("B" & I20)} -> NIVEL 1018 FRENTE AM 59 30-12-2025 | K20: =INDEX(D:D, MATCH(J20, $B:$B, 0)) -> 3.5 | L20: =INDEX(E:E, MATCH(J20, $B:$B, 0))*0.9 -> 0.01404 | M20: =INDEX(F:F, MATCH(J20, $B:$B, 0)) -> 0 | N20: =+IF(L20=0,M20*0.9,L20*0.9) -> 0.012636 | O20: =+IF(L20=0,"-","Dump") -> Dump | P20: =+K20/5.6 -> 0.625 | R20: N°Lote | S20: Camionada | T20: Ticket | U20: Patente | V20: Fecha Despacho | W20: Fecha Recepción | X20: Hora | Y20: Peso | Z20: Ley mezcla | AA20: Ley Visual | AB20: Origen | AC20: Ley Lab Camion | AD20: Diferencia | AE20: % Error
B21: NIVEL 1018 REC AM 14 27-12-2025 | C21: 1 | D21: 3.5 | E21: 0.02 | H21: 80 | I21: =IF(H21="", IFERROR(MATCH("**", B:B, 0), ""), IFERROR(MATCH("* "&H21&" *", B:B, 0), "") ) -> 87 | J21: {=INDIRECT("B" & I21)} -> NIVEL 1018 FRENTE AM 80 31-12-2025 | K21: =INDEX(D:D, MATCH(J21, $B:$B, 0)) -> 3.5 | L21: =INDEX(E:E, MATCH(J21, $B:$B, 0))*0.9 -> 0.01935 | M21: =INDEX(F:F, MATCH(J21, $B:$B, 0)) -> 0 | N21: =+IF(L21=0,M21*0.9,L21*0.9) -> 0.017415 | O21: =+IF(L21=0,"-","Dump") -> Dump | P21: =+K21/5.6 -> 0.625 | R21: CN002 | S21: 1 | U21: PYCH-48 | V21: 46036 | W21: 46036 | Y21: 28.88 | Z21: =+L100 -> 0.019078788 | AA21: =+M99 -> 0 | AB21: =+I65 -> CN002 | AD21: =+AC32-Z32 -> -0.019528269 | AE21: =+(AC32-Z32)/Z32 -> -1
B22: NIVEL 1018 REC AM 15 27-12-2025 | C22: 1 | D22: 3.5 | E22: 0.02 | H22: 81 | I22: =IF(H22="", IFERROR(MATCH("**", B:B, 0), ""), IFERROR(MATCH("* "&H22&" *", B:B, 0), "") ) -> 88 | J22: {=INDIRECT("B" & I22)} -> NIVEL 1018 FRENTE AM 81 31-12-2025 | K22: =INDEX(D:D, MATCH(J22, $B:$B, 0)) -> 3.5 | L22: =INDEX(E:E, MATCH(J22, $B:$B, 0))*0.9 -> 0.01611 | M22: =INDEX(F:F, MATCH(J22, $B:$B, 0)) -> 0 | N22: =+IF(L22=0,M22*0.9,L22*0.9) -> 0.014499 | O22: =+IF(L22=0,"-","Dump") -> Dump | P22: =+K22/5.6 -> 0.625 | R22: 3H COPPER EL SAUCE 1 AL 5 | S22: 2 | U22: LCGZ-26 | V22: 46036 | W22: 46036 | Y22: 29.71 | Z22: =+L100 -> 0.019078788 | AA22: =+M99 -> 0 | AB22: =+I65 -> CN002
B23: NIVEL 1018 REC AM 16 27-12-2025 | C23: 1 | D23: 3.5 | E23: 0.02 | H23: 82 | I23: =IF(H23="", IFERROR(MATCH("**", B:B, 0), ""), IFERROR(MATCH("* "&H23&" *", B:B, 0), "") ) -> 89 | J23: {=INDIRECT("B" & I23)} -> NIVEL 1018 FRENTE AM 82 31-12-2025 | K23: =INDEX(D:D, MATCH(J23, $B:$B, 0)) -> 3.5 | L23: =INDEX(E:E, MATCH(J23, $B:$B, 0))*0.9 -> 0.01107 | M23: =INDEX(F:F, MATCH(J23, $B:$B, 0)) -> 0 | N23: =+IF(L23=0,M23*0.9,L23*0.9) -> 0.009963 | O23: =+IF(L23=0,"-","Dump") -> Dump | P23: =+K23/5.6 -> 0.625 | S23: 3 | U23: PYCH-48 | V23: 46037 | W23: 46037 | Y23: 29.52 | Z23: =+L135 -> 0.019745161 | AA23: =+M134 -> 0 | AB23: =+I102 -> CN003
B24: NIVEL 1018 REC AM 17 27-12-2025 | C24: 1 | D24: 3.5 | E24: 0.02 | H24: 83 | I24: =IF(H24="", IFERROR(MATCH("**", B:B, 0), ""), IFERROR(MATCH("* "&H24&" *", B:B, 0), "") ) -> 90 | J24: {=INDIRECT("B" & I24)} -> NIVEL 1018 FRENTE AM 83 31-12-2025 | K24: =INDEX(D:D, MATCH(J24, $B:$B, 0)) -> 3.5 | L24: =INDEX(E:E, MATCH(J24, $B:$B, 0))*0.9 -> 0.01485 | M24: =INDEX(F:F, MATCH(J24, $B:$B, 0)) -> 0 | N24: =+IF(L24=0,M24*0.9,L24*0.9) -> 0.013365 | O24: =+IF(L24=0,"-","Dump") -> Dump | P24: =+K24/5.6 -> 0.625 | S24: 4 | U24: PYCH-48 | V24: 46037 | W24: 46037 | Y24: 30.1 | Z24: =+L135 -> 0.019745161 | AA24: =+M134 -> 0 | AB24: =+I102 -> CN003
B25: NIVEL 1018 REC AM 18 27-12-2025 | C25: 1 | D25: 3.5 | E25: 0.02 | H25: 89 | I25: =IF(H25="", IFERROR(MATCH("**", B:B, 0), ""), IFERROR(MATCH("* "&H25&" *", B:B, 0), "") ) -> 96 | J25: {=INDIRECT("B" & I25)} -> NIVEL 789 REC AM 89 31-12-2025 | K25: =INDEX(D:D, MATCH(J25, $B:$B, 0)) -> 3.5 | L25: =INDEX(E:E, MATCH(J25, $B:$B, 0))*0.9 -> 0.02178 | M25: =INDEX(F:F, MATCH(J25, $B:$B, 0)) -> 0 | N25: =+IF(L25=0,M25*0.9,L25*0.9) -> 0.019602 | O25: =+IF(L25=0,"-","Dump") -> Dump | P25: =+K25/5.6 -> 0.625 | S25: 5 | U25: LCGZ-26 | V25: 46038 | W25: 46038 | Y25: 31.8 | Z25: =+L135 -> 0.019745161 | AA25: =+M134 -> 0 | AB25: =+I102 -> CN003
B26: NIVEL 1018 REC AM 19 27-12-2025 | C26: 1 | D26: 3.5 | E26: 0.02 | H26: 90 | I26: =IF(H26="", IFERROR(MATCH("**", B:B, 0), ""), IFERROR(MATCH("* "&H26&" *", B:B, 0), "") ) -> 97 | J26: {=INDIRECT("B" & I26)} -> NIVEL 789 REC AM 90 31-12-2025 | K26: =INDEX(D:D, MATCH(J26, $B:$B, 0)) -> 3.5 | L26: =INDEX(E:E, MATCH(J26, $B:$B, 0))*0.9 -> 0.01035 | M26: =INDEX(F:F, MATCH(J26, $B:$B, 0)) -> 0 | N26: =+IF(L26=0,M26*0.9,L26*0.9) -> 0.009315 | O26: =+IF(L26=0,"-","Dump") -> Dump | P26: =+K26/5.6 -> 0.625 | S26: 6 | U26: PYCH-48 | V26: 46038 | W26: 46038 | Y26: 30 | Z26: =+L135 -> 0.019745161 | AA26: =+M134 -> 0 | AB26: =+I102 -> CN003
B27: NIVEL 1018 REC AM 20 27-12-2025 | C27: 1 | D27: 3.5 | E27: 0.02 | H27: 91 | I27: =IF(H27="", IFERROR(MATCH("**", B:B, 0), ""), IFERROR(MATCH("* "&H27&" *", B:B, 0), "") ) -> 98 | J27: {=INDIRECT("B" & I27)} -> NIVEL 789 REC AM 91 31-12-2025 | K27: =INDEX(D:D, MATCH(J27, $B:$B, 0)) -> 3.5 | L27: =INDEX(E:E, MATCH(J27, $B:$B, 0))*0.9 -> 0.01449 | M27: =INDEX(F:F, MATCH(J27, $B:$B, 0)) -> 0 | N27: =+IF(L27=0,M27*0.9,L27*0.9) -> 0.013041 | O27: =+IF(L27=0,"-","Dump") -> Dump | P27: =+K27/5.6 -> 0.625 | S27: 7
B28: NIVEL 1018 REC AM 21 27-12-2025 | C28: 1 | D28: 3.5 | E28: 0.02 | H28: 92 | I28: =IF(H28="", IFERROR(MATCH("**", B:B, 0), ""), IFERROR(MATCH("* "&H28&" *", B:B, 0), "") ) -> 99 | J28: {=INDIRECT("B" & I28)} -> NIVEL 789 REC AM 92 31-12-2025 | K28: =INDEX(D:D, MATCH(J28, $B:$B, 0)) -> 3.5 | L28: =INDEX(E:E, MATCH(J28, $B:$B, 0))*0.9 -> 0.01188 | M28: =INDEX(F:F, MATCH(J28, $B:$B, 0)) -> 0 | N28: =+IF(L28=0,M28*0.9,L28*0.9) -> 0.010692 | O28: =+IF(L28=0,"-","Dump") -> Dump | P28: =+K28/5.6 -> 0.625 | S28: 8
B29: NIVEL 1018 REC AM 22 27-12-2025 | C29: 1 | D29: 3.5 | E29: 0.02 | H29: 93 | I29: =IF(H29="", IFERROR(MATCH("**", B:B, 0), ""), IFERROR(MATCH("* "&H29&" *", B:B, 0), "") ) -> 100 | J29: {=INDIRECT("B" & I29)} -> NIVEL 789 REC AM 93 31-12-2025 | K29: =INDEX(D:D, MATCH(J29, $B:$B, 0)) -> 3.5 | L29: =INDEX(E:E, MATCH(J29, $B:$B, 0))*0.9 -> 0.02151 | M29: =INDEX(F:F, MATCH(J29, $B:$B, 0)) -> 0 | N29: =+IF(L29=0,M29*0.9,L29*0.9) -> 0.019359 | O29: =+IF(L29=0,"-","Dump") -> Dump | P29: =+K29/5.6 -> 0.625 | S29: 9
B30: NIVEL 1018 REC AM 23 27-12-2025 | C30: 1 | D30: 3.5 | E30: 0.02 | H30: 94 | I30: =IF(H30="", IFERROR(MATCH("**", B:B, 0), ""), IFERROR(MATCH("* "&H30&" *", B:B, 0), "") ) -> 101 | J30: {=INDIRECT("B" & I30)} -> NIVEL 789 REC AM 94 31-12-2025 | K30: =INDEX(D:D, MATCH(J30, $B:$B, 0)) -> 3.5 | L30: =INDEX(E:E, MATCH(J30, $B:$B, 0))*0.9 -> 0.01494 | M30: =INDEX(F:F, MATCH(J30, $B:$B, 0)) -> 0 | N30: =+IF(L30=0,M30*0.9,L30*0.9) -> 0.013446 | O30: =+IF(L30=0,"-","Dump") -> Dump | P30: =+K30/5.6 -> 0.625 | S30: 10
B31: NIVEL 1018 REC AM 24 27-12-2025 | C31: 1 | D31: 3.5 | E31: 0.02 | H31: 95 | I31: =IF(H31="", IFERROR(MATCH("**", B:B, 0), ""), IFERROR(MATCH("* "&H31&" *", B:B, 0), "") ) -> 102 | J31: {=INDIRECT("B" & I31)} -> NIVEL 789 REC AM 95 31-12-2025 | K31: =INDEX(D:D, MATCH(J31, $B:$B, 0)) -> 3.5 | L31: =INDEX(E:E, MATCH(J31, $B:$B, 0))*0.9 -> 0.01044 | M31: =INDEX(F:F, MATCH(J31, $B:$B, 0)) -> 0 | N31: =+IF(L31=0,M31*0.9,L31*0.9) -> 0.009396 | O31: =+IF(L31=0,"-","Dump") -> Dump | P31: =+K31/5.6 -> 0.625 | S31: 11
B32: NIVEL 1018 REC AM 25 27-12-2025 | C32: 1 | D32: 3.5 | E32: 0.02 | H32: 96 | I32: =IF(H32="", IFERROR(MATCH("**", B:B, 0), ""), IFERROR(MATCH("* "&H32&" *", B:B, 0), "") ) -> 103 | J32: {=INDIRECT("B" & I32)} -> NIVEL 789 REC AM 96 31-12-2025 | K32: =INDEX(D:D, MATCH(J32, $B:$B, 0)) -> 3.5 | L32: =INDEX(E:E, MATCH(J32, $B:$B, 0))*0.9 -> 0.01377 | M32: =INDEX(F:F, MATCH(J32, $B:$B, 0)) -> 0 | N32: =+IF(L32=0,M32*0.9,L32*0.9) -> 0.012393 | O32: =+IF(L32=0,"-","Dump") -> Dump | P32: =+K32/5.6 -> 0.625 | Y32: =SUM(Y21:Y31) -> 180.01 | Z32: =+SUMPRODUCT(Y21:Y31,Z21:Z31)/Y32 -> 0.019528269 | AA32: =+SUMPRODUCT(Y21:Y31,AA21:AA31)/Y32 -> 0 | AC32: 0
B33: NIVEL 1018 REC AM 26 27-12-2025 | C33: 1 | D33: 3.5 | E33: 0.02 | H33: 97 | I33: =IF(H33="", IFERROR(MATCH("**", B:B, 0), ""), IFERROR(MATCH("* "&H33&" *", B:B, 0), "") ) -> 104 | J33: {=INDIRECT("B" & I33)} -> NIVEL 789 REC AM 97 31-12-2025 | K33: =INDEX(D:D, MATCH(J33, $B:$B, 0)) -> 3.5 | L33: =INDEX(E:E, MATCH(J33, $B:$B, 0))*0.9 -> 0.01485 | M33: =INDEX(F:F, MATCH(J33, $B:$B, 0)) -> 0 | N33: =+IF(L33=0,M33*0.9,L33*0.9) -> 0.013365 | O33: =+IF(L33=0,"-","Dump") -> Dump | P33: =+K33/5.6 -> 0.625
B34: NIVEL 1018 REC AM 27 27-12-2025 | C34: 1 | D34: 3.5 | E34: 0.02 | H34: 98 | I34: =IF(H34="", IFERROR(MATCH("**", B:B, 0), ""), IFERROR(MATCH("* "&H34&" *", B:B, 0), "") ) -> 105 | J34: {=INDIRECT("B" & I34)} -> NIVEL 1018 FRENTE PM 98 05-01-2026 | K34: =INDEX(D:D, MATCH(J34, $B:$B, 0)) -> 3.5 | L34: =INDEX(E:E, MATCH(J34, $B:$B, 0))*0.9 -> 0.009 | M34: =INDEX(F:F, MATCH(J34, $B:$B, 0)) -> 0 | N34: =+IF(L34=0,M34*0.9,L34*0.9) -> 0.0081 | O34: =+IF(L34=0,"-","Dump") -> Dump | P34: =+K34/5.6 -> 0.625 | R34: N°Lote | S34: Camionada | T34: Ticket | U34: Patente | V34: Fecha Despacho | W34: Fecha Recepción | X34: Hora | Y34: Peso | Z34: Ley mezcla | AA34: Ley Visual | AB34: Origen | AC34: Ley Lab Camion | AD34: Diferencia | AE34: % Error
B35: NIVEL 970 SELLO AM 28 27-12-2025 | C35: 1 | D35: 3.5 | E35: 0.0164 | H35: 99 | I35: =IF(H35="", IFERROR(MATCH("**", B:B, 0), ""), IFERROR(MATCH("* "&H35&" *", B:B, 0), "") ) -> 106 | J35: {=INDIRECT("B" & I35)} -> NIVEL 1018 FRENTE PM 99 05-01-2026 | K35: =INDEX(D:D, MATCH(J35, $B:$B, 0)) -> 3.5 | L35: =INDEX(E:E, MATCH(J35, $B:$B, 0))*0.9 -> 0.009 | M35: =INDEX(F:F, MATCH(J35, $B:$B, 0)) -> 0 | N35: =+IF(L35=0,M35*0.9,L35*0.9) -> 0.0081 | O35: =+IF(L35=0,"-","Dump") -> Dump | P35: =+K35/5.6 -> 0.625 | R35: CN003 | S35: 1 | U35: PYCH-48 | V35: 46041 | W35: 46041 | Y35: 30 | Z35: =+L156 -> 0.019558824 | AA35: =+M155 -> 0 | AB35: =+I137 -> CN004 | AD35: =+AC46-Z46 -> -0.01779752 | AE35: =+(AC46-Z46)/Z46 -> -1
B36: NIVEL 970 SELLO AM 29 27-12-2025 | C36: 1 | D36: 3.5 | E36: 0.0164 | H36: 100 | I36: =IF(H36="", IFERROR(MATCH("**", B:B, 0), ""), IFERROR(MATCH("* "&H36&" *", B:B, 0), "") ) -> 107 | J36: {=INDIRECT("B" & I36)} -> NIVEL 1018 FRENTE PM 100 05-01-2026 | K36: =INDEX(D:D, MATCH(J36, $B:$B, 0)) -> 3.5 | L36: =INDEX(E:E, MATCH(J36, $B:$B, 0))*0.9 -> 0.01773 | M36: =INDEX(F:F, MATCH(J36, $B:$B, 0)) -> 0 | N36: =+IF(L36=0,M36*0.9,L36*0.9) -> 0.015957 | O36: =+IF(L36=0,"-","Dump") -> Dump | P36: =+K36/5.6 -> 0.625 | R36: 3H COPPER EL SAUCE 1 AL 5 | S36: 2 | U36: RBWX-10 | V36: 46041 | W36: 46041 | Y36: 25.1 | Z36: =+L156 -> 0.019558824 | AA36: =+M155 -> 0 | AB36: =+I137 -> CN004
B37: NIVEL 970 SELLO AM 30 27-12-2025 | C37: 1 | D37: 3.5 | E37: 0.0164 | H37: 101 | I37: =IF(H37="", IFERROR(MATCH("**", B:B, 0), ""), IFERROR(MATCH("* "&H37&" *", B:B, 0), "") ) -> 108 | J37: {=INDIRECT("B" & I37)} -> NIVEL 1018 FRENTE PM 101 05-01-2026 | K37: =INDEX(D:D, MATCH(J37, $B:$B, 0)) -> 3.5 | L37: =INDEX(E:E, MATCH(J37, $B:$B, 0))*0.9 -> 0.01638 | M37: =INDEX(F:F, MATCH(J37, $B:$B, 0)) -> 0 | N37: =+IF(L37=0,M37*0.9,L37*0.9) -> 0.014742 | O37: =+IF(L37=0,"-","Dump") -> Dump | P37: =+K37/5.6 -> 0.625 | S37: 3 | U37: LCGZ-26 | V37: 46041 | W37: 46042 | Y37: 28.98 | Z37: =+L208 -> 0.016152083 | AA37: =+M207 -> 0 | AB37: =+I158 -> CN005
